Workbook

Sheet Prompt
A1: Updated Prompt / Modelling Instruction
A2: This tab documents the final modelling instruction applied to the workbook, including the requested treatment of unreconciled balances.
A4: Area | B4: Instruction
A5: Source statements | B5: Use the financial statements PDF, extract the P&L and balance sheet into Excel, express figures in EUR thousands with no decimals, and keep separate P&L and balance sheet tabs.
A6: Cash flow source rule | B6: Add direct and indirect cash flow tabs calculated with formulas. Do not use the published company cash flow statement.
A7: Unreconciled balance treatment | B7: In both the direct and indirect cash flow tabs, include the unreconciled balance as a line within the cash-flow bridge, not outside it. The unreconciled balance must be part of the total cash movement and therefore part of the ending cash balance calculation.
A8: Why unreconciled is not further reconciled | B8: Explain clearly in the workbook that the unreconciled balance is not further reconciled because the permitted source set is limited to the P&L and balance sheet, while a full reconciliation would require note-level cash, FX, non-cash, perimeter/M&A, and classification disclosures or the published cash flow statement. Do not invent figures or force manual adjustments to make the residual disappear.
A9: Ending balance tie-out | B9: In both the direct and indirect cash flow tabs, ending cash balance must equal opening cash balance plus total cash movement including the unreconciled balance, and must reconcile to the cash balance reported on the balance sheet.
A10: Equity presentation | B10: Show equity in detail and separate retained earnings from current-period net income.
A11: Indirect cash flow start point | B11: Start the indirect cash flow from net income.
A12: Professional standard | B12: Behave like a senior FP&A professional: do not invent figures, do not force manual adjustments, use formulas, source/note columns, clear checks, and make the workbook easy to read, audit, and challenge.
A13: Formatting | B13: Use a polished senior FP&A format with merged title/subtitle rows, readable Arial font, wide columns, wrapped methodology notes, frozen panes, clear section headers, bold subtotal rows, light blue section fills, light grey subtotal fills, red-highlighted unreconciled/control lines, and thousands number format with no decimals for all financial figures.

Sheet P&L
A1: Banco Santander - Consolidated P&L
A2: EUR thousands, no decimals. Source statement reports EUR millions; each source amount is scaled by 1,000. Translation from Spanish source labels is for readability only.
A4: Line item | B4: Note | C4: 2025 | D4: 2024 | E4: 2023 | F4: Source | G4: Methodology / audit note
A5: Interest income | B5: 38 | C5: 101710000 | D5: 109012000 | E5: 101742000 | F5: Banco Santander Consolidado 2025 2024.pdf; EURm x1,000 to EURk P&L p.654. | G5: Extracted from the consolidated income statement; no cash flow statement values used.
A6: Financial assets at fair value through other comprehensive income | C6: 5713000 | D6: 6931000 | E6: 5533000 | F6: Banco Santander Consolidado 2025 2024.pdf; EURm x1,000 to EURk P&L p.654. | G6: Extracted from the consolidated income statement; no cash flow statement values used.
A7: Financial assets at amortised cost | C7: 76248000 | D7: 80992000 | E7: 74799000 | F7: Banco Santander Consolidado 2025 2024.pdf; EURm x1,000 to EURk P&L p.654. | G7: Extracted from the consolidated income statement; no cash flow statement values used.
A8: Remaining interest income | C8: 19749000 | D8: 21089000 | E8: 21410000 | F8: Banco Santander Consolidado 2025 2024.pdf; EURm x1,000 to EURk P&L p.654. | G8: Extracted from the consolidated income statement; no cash flow statement values used.
A9: Interest expense | B9: 39 | C9: -59362000 | D9: -65225000 | E9: -61092000 | F9: Banco Santander Consolidado 2025 2024.pdf; EURm x1,000 to EURk P&L p.654. | G9: Extracted from the consolidated income statement; no cash flow statement values used.
A10: Net interest income | C10: 42348000 | D10: 43787000 | E10: 40650000 | F10: Banco Santander Consolidado 2025 2024.pdf; EURm x1,000 to EURk P&L p.654. | G10: Extracted from the consolidated income statement; no cash flow statement values used.
A11: Dividend income | B11: 40 | C11: 715000 | D11: 710000 | E11: 568000 | F11: Banco Santander Consolidado 2025 2024.pdf; EURm x1,000 to EURk P&L p.654. | G11: Extracted from the consolidated income statement; no cash flow statement values used.
A12: Share of results of entities accounted for using the equity method | B12: 13 | C12: 665000 | D12: 687000 | E12: 591000 | F12: Banco Santander Consolidado 2025 2024.pdf; EURm x1,000 to EURk P&L p.654. | G12: Extracted from the consolidated income statement; no cash flow statement values used.
A13: Fee and commission income | B13: 41 | C13: 17387000 | D13: 16834000 | E13: 15644000 | F13: Banco Santander Consolidado 2025 2024.pdf; EURm x1,000 to EURk P&L p.654. | G13: Extracted from the consolidated income statement; no cash flow statement values used.
A14: Fee and commission expense | B14: 42 | C14: -4411000 | D14: -4458000 | E14: -4149000 | F14: Banco Santander Consolidado 2025 2024.pdf; EURm x1,000 to EURk P&L p.654. | G14: Extracted from the consolidated income statement; no cash flow statement values used.
A15: Gains/losses on derecognition of financial assets and liabilities not measured at FVPL, net | B15: 43 | C15: 127000 | D15: -117000 | E15: 96000 | F15: Banco Santander Consolidado 2025 2024.pdf; EURm x1,000 to EURk P&L p.654. | G15: Extracted from the consolidated income statement; no cash flow statement values used.
A16: Financial assets at amortised cost | C16: -89000 | D16: -190000 | E16: -3000 | F16: Banco Santander Consolidado 2025 2024.pdf; EURm x1,000 to EURk P&L p.654. | G16: Extracted from the consolidated income statement; no cash flow statement values used.
A17: Remaining financial assets and liabilities | C17: 216000 | D17: 73000 | E17: 99000 | F17: Banco Santander Consolidado 2025 2024.pdf; EURm x1,000 to EURk P&L p.654. | G17: Extracted from the consolidated income statement; no cash flow statement values used.
A18: Gains/losses on financial assets and liabilities held for trading, net | B18: 43 | C18: 1017000 | D18: 1344000 | E18: 2316000 | F18: Banco Santander Consolidado 2025 2024.pdf; EURm x1,000 to EURk P&L p.654. | G18: Extracted from the consolidated income statement; no cash flow statement values used.
A19: Other gains or losses - trading | C19: 1017000 | D19: 1344000 | E19: 2316000 | F19: Banco Santander Consolidado 2025 2024.pdf; EURm x1,000 to EURk P&L p.654. | G19: Extracted from the consolidated income statement; no cash flow statement values used.
A20: Gains/losses on non-trading financial assets mandatorily at FVPL, net | B20: 43 | C20: 1106000 | D20: 495000 | E20: 198000 | F20: Banco Santander Consolidado 2025 2024.pdf; EURm x1,000 to EURk P&L p.654. | G20: Extracted from the consolidated income statement; no cash flow statement values used.
A21: Other gains or losses - non-trading FVPL | C21: 1106000 | D21: 495000 | E21: 198000 | F21: Banco Santander Consolidado 2025 2024.pdf; EURm x1,000 to EURk P&L p.654. | G21: Extracted from the consolidated income statement; no cash flow statement values used.
A22: Gains/losses on financial assets and liabilities designated at FVPL, net | B22: 43 | C22: -307000 | D22: 691000 | E22: -92000 | F22: Banco Santander Consolidado 2025 2024.pdf; EURm x1,000 to EURk P&L p.654. | G22: Extracted from the consolidated income statement; no cash flow statement values used.
A23: Gains/losses from hedge accounting, net | B23: 43 | C23: 12000 | D23: 14000 | E23: 69000 | F23: Banco Santander Consolidado 2025 2024.pdf; EURm x1,000 to EURk P&L p.654. | G23: Extracted from the consolidated income statement; no cash flow statement values used.
A24: Exchange differences, net | B24: 44 | C24: 407000 | D24: -216000 | E24: -22000 | F24: Banco Santander Consolidado 2025 2024.pdf; EURm x1,000 to EURk P&L p.654. | G24: Extracted from the consolidated income statement; no cash flow statement values used.
A25: Other operating income | B25: 45 | C25: 1583000 | D25: 846000 | E25: 1137000 | F25: Banco Santander Consolidado 2025 2024.pdf; EURm x1,000 to EURk P&L p.654. | G25: Extracted from the consolidated income statement; no cash flow statement values used.
A26: Other operating expenses | B26: 45 | C26: -2070000 | D26: -2258000 | E26: -2766000 | F26: Banco Santander Consolidado 2025 2024.pdf; EURm x1,000 to EURk P&L p.654. | G26: Extracted from the consolidated income statement; no cash flow statement values used.
A27: Income from insurance or reinsurance contracts | C27: 476000 | D27: 470000 | E27: 460000 | F27: Banco Santander Consolidado 2025 2024.pdf; EURm x1,000 to EURk P&L p.654. | G27: Extracted from the consolidated income statement; no cash flow statement values used.
A28: Expenses from insurance or reinsurance contracts | C28: -385000 | D28: -449000 | E28: -449000 | F28: Banco Santander Consolidado 2025 2024.pdf; EURm x1,000 to EURk P&L p.654. | G28: Extracted from the consolidated income statement; no cash flow statement values used.
A29: Gross income | C29: 58670000 | D29: 58380000 | E29: 54251000 | F29: Banco Santander Consolidado 2025 2024.pdf; EURm x1,000 to EURk P&L p.655. | G29: Extracted from the consolidated income statement; no cash flow statement values used.
A30: Administrative expenses | C30: -21533000 | D30: -21970000 | E30: -21546000 | F30: Banco Santander Consolidado 2025 2024.pdf; EURm x1,000 to EURk P&L p.655. | G30: Extracted from the consolidated income statement; no cash flow statement values used.
A31: Staff costs | B31: 46 | C31: -13633000 | D31: -13825000 | E31: -13275000 | F31: Banco Santander Consolidado 2025 2024.pdf; EURm x1,000 to EURk P&L p.655. | G31: Extracted from the consolidated income statement; no cash flow statement values used.
A32: Other administrative expenses | B32: 47 | C32: -7900000 | D32: -8145000 | E32: -8271000 | F32: Banco Santander Consolidado 2025 2024.pdf; EURm x1,000 to EURk P&L p.655. | G32: Extracted from the consolidated income statement; no cash flow statement values used.
A33: Depreciation and amortisation | B33: 16,18 | C33: -3178000 | D33: -3179000 | E33: -3086000 | F33: Banco Santander Consolidado 2025 2024.pdf; EURm x1,000 to EURk P&L p.655. | G33: Extracted from the consolidated income statement; no cash flow statement values used.
A34: Provisions or reversal of provisions | B34: 25 | C34: -2729000 | D34: -3465000 | E34: -2410000 | F34: Banco Santander Consolidado 2025 2024.pdf; EURm x1,000 to EURk P&L p.655. | G34: Extracted from the consolidated income statement; no cash flow statement values used.
A35: Impairment/reversal of impairment on financial assets not at FVPL and net modification gains/losses | C35: -12546000 | D35: -12136000 | E35: -12298000 | F35: Banco Santander Consolidado 2025 2024.pdf; EURm x1,000 to EURk P&L p.655. | G35: Extracted from the consolidated income statement; no cash flow statement values used.
A36: Financial assets at FVOCI | C36: -29000 | D36: 1000 | E36: -24000 | F36: Banco Santander Consolidado 2025 2024.pdf; EURm x1,000 to EURk P&L p.655. | G36: Extracted from the consolidated income statement; no cash flow statement values used.
A37: Financial assets at amortised cost | B37: 10 | C37: -12517000 | D37: -12137000 | E37: -12274000 | F37: Banco Santander Consolidado 2025 2024.pdf; EURm x1,000 to EURk P&L p.655. | G37: Extracted from the consolidated income statement; no cash flow statement values used.
A38: Impairment/reversal of impairment of investments in joint ventures or associates | B38: 17,18 | C38: 0 | D38: 0 | E38: 0 | F38: Banco Santander Consolidado 2025 2024.pdf; EURm x1,000 to EURk P&L p.655. | G38: Extracted from the consolidated income statement; no cash flow statement values used.
A39: Impairment/reversal of impairment of non-financial assets | C39: -251000 | D39: -624000 | E39: -237000 | F39: Banco Santander Consolidado 2025 2024.pdf; EURm x1,000 to EURk P&L p.655. | G39: Extracted from the consolidated income statement; no cash flow statement values used.
A40: Tangible assets | B40: 16 | C40: -129000 | D40: -382000 | E40: -135000 | F40: Banco Santander Consolidado 2025 2024.pdf; EURm x1,000 to EURk P&L p.655. | G40: Extracted from the consolidated income statement; no cash flow statement values used.
A41: Intangible assets | B41: 17,18 | C41: -112000 | D41: -231000 | E41: -73000 | F41: Banco Santander Consolidado 2025 2024.pdf; EURm x1,000 to EURk P&L p.655. | G41: Extracted from the consolidated income statement; no cash flow statement values used.
...

Sheet Balance Sheet
A1: Banco Santander - Consolidated Balance Sheet
A2: EUR thousands, no decimals. Equity is shown in detail and retained earnings are separate from current-period net income attributable to owners of the parent.
A4: Line item | B4: Note | C4: 2025 | D4: 2024 | E4: 2023 | F4: Source | G4: Methodology / audit note
A5: ASSETS
A6: Cash, balances at central banks and other demand deposits | C6: 152281000 | D6: 192208000 | E6: 220342000 | F6: Banco Santander Consolidado 2025 2024.pdf; EURm x1,000 to EURk BS p.650. | G6: Extracted from the consolidated balance sheet; no cash flow statement values used.
A7: Financial assets held for trading | C7: 252318000 | D7: 230253000 | E7: 176921000 | F7: Banco Santander Consolidado 2025 2024.pdf; EURm x1,000 to EURk BS p.650. | G7: Extracted from the consolidated balance sheet; no cash flow statement values used.
A8: Derivatives | B8: 9,11 | C8: 58355000 | D8: 64100000 | E8: 56328000 | F8: Banco Santander Consolidado 2025 2024.pdf; EURm x1,000 to EURk BS p.650. | G8: Extracted from the consolidated balance sheet; no cash flow statement values used.
A9: Equity instruments | B9: 8 | C9: 22030000 | D9: 16636000 | E9: 15057000 | F9: Banco Santander Consolidado 2025 2024.pdf; EURm x1,000 to EURk BS p.650. | G9: Extracted from the consolidated balance sheet; no cash flow statement values used.
A10: Debt securities | B10: 7 | C10: 98568000 | D10: 82646000 | E10: 62124000 | F10: Banco Santander Consolidado 2025 2024.pdf; EURm x1,000 to EURk BS p.650. | G10: Extracted from the consolidated balance sheet; no cash flow statement values used.
A11: Loans and advances | C11: 73365000 | D11: 66871000 | E11: 43412000 | F11: Banco Santander Consolidado 2025 2024.pdf; EURm x1,000 to EURk BS p.650. | G11: Extracted from the consolidated balance sheet; no cash flow statement values used.
A12: Central banks | B12: 6 | C12: 14632000 | D12: 12966000 | E12: 17717000 | F12: Banco Santander Consolidado 2025 2024.pdf; EURm x1,000 to EURk BS p.650. | G12: Extracted from the consolidated balance sheet; no cash flow statement values used.
A13: Credit institutions | B13: 6 | C13: 25967000 | D13: 27314000 | E13: 14061000 | F13: Banco Santander Consolidado 2025 2024.pdf; EURm x1,000 to EURk BS p.650. | G13: Extracted from the consolidated balance sheet; no cash flow statement values used.
A14: Customers | B14: 10 | C14: 32766000 | D14: 26591000 | E14: 11634000 | F14: Banco Santander Consolidado 2025 2024.pdf; EURm x1,000 to EURk BS p.650. | G14: Extracted from the consolidated balance sheet; no cash flow statement values used.
A15: Financial assets not held for trading mandatorily at FVPL | C15: 7761000 | D15: 6130000 | E15: 5910000 | F15: Banco Santander Consolidado 2025 2024.pdf; EURm x1,000 to EURk BS p.650. | G15: Extracted from the consolidated balance sheet; no cash flow statement values used.
A16: Equity instruments | B16: 8 | C16: 5815000 | D16: 4641000 | E16: 4068000 | F16: Banco Santander Consolidado 2025 2024.pdf; EURm x1,000 to EURk BS p.650. | G16: Extracted from the consolidated balance sheet; no cash flow statement values used.
A17: Debt securities | B17: 7 | C17: 245000 | D17: 447000 | E17: 860000 | F17: Banco Santander Consolidado 2025 2024.pdf; EURm x1,000 to EURk BS p.650. | G17: Extracted from the consolidated balance sheet; no cash flow statement values used.
A18: Loans and advances | C18: 1701000 | D18: 1042000 | E18: 982000 | F18: Banco Santander Consolidado 2025 2024.pdf; EURm x1,000 to EURk BS p.650. | G18: Extracted from the consolidated balance sheet; no cash flow statement values used.
A19: Financial assets designated at FVPL | C19: 8046000 | D19: 7915000 | E19: 9773000 | F19: Banco Santander Consolidado 2025 2024.pdf; EURm x1,000 to EURk BS p.650. | G19: Extracted from the consolidated balance sheet; no cash flow statement values used.
A20: Debt securities | B20: 7 | C20: 2894000 | D20: 2897000 | E20: 3095000 | F20: Banco Santander Consolidado 2025 2024.pdf; EURm x1,000 to EURk BS p.650. | G20: Extracted from the consolidated balance sheet; no cash flow statement values used.
A21: Loans and advances | C21: 5152000 | D21: 5018000 | E21: 6678000 | F21: Banco Santander Consolidado 2025 2024.pdf; EURm x1,000 to EURk BS p.650. | G21: Extracted from the consolidated balance sheet; no cash flow statement values used.
A22: Financial assets at fair value through OCI | C22: 74612000 | D22: 89898000 | E22: 83308000 | F22: Banco Santander Consolidado 2025 2024.pdf; EURm x1,000 to EURk BS p.650. | G22: Extracted from the consolidated balance sheet; no cash flow statement values used.
A23: Equity instruments | B23: 8 | C23: 2281000 | D23: 2193000 | E23: 1761000 | F23: Banco Santander Consolidado 2025 2024.pdf; EURm x1,000 to EURk BS p.650. | G23: Extracted from the consolidated balance sheet; no cash flow statement values used.
A24: Debt securities | B24: 7 | C24: 58305000 | D24: 76558000 | E24: 73565000 | F24: Banco Santander Consolidado 2025 2024.pdf; EURm x1,000 to EURk BS p.650. | G24: Extracted from the consolidated balance sheet; no cash flow statement values used.
A25: Loans and advances | C25: 14026000 | D25: 11147000 | E25: 7982000 | F25: Banco Santander Consolidado 2025 2024.pdf; EURm x1,000 to EURk BS p.650. | G25: Extracted from the consolidated balance sheet; no cash flow statement values used.
A26: Financial assets at amortised cost | C26: 1202689000 | D26: 1203707000 | E26: 1191403000 | F26: Banco Santander Consolidado 2025 2024.pdf; EURm x1,000 to EURk BS p.650. | G26: Extracted from the consolidated balance sheet; no cash flow statement values used.
A27: Debt securities | B27: 7 | C27: 140014000 | D27: 120949000 | E27: 103559000 | F27: Banco Santander Consolidado 2025 2024.pdf; EURm x1,000 to EURk BS p.650. | G27: Extracted from the consolidated balance sheet; no cash flow statement values used.
A28: Loans and advances | C28: 1062675000 | D28: 1082758000 | E28: 1087844000 | F28: Banco Santander Consolidado 2025 2024.pdf; EURm x1,000 to EURk BS p.650. | G28: Extracted from the consolidated balance sheet; no cash flow statement values used.
A29: Central banks | B29: 6 | C29: 15986000 | D29: 16179000 | E29: 20082000 | F29: Banco Santander Consolidado 2025 2024.pdf; EURm x1,000 to EURk BS p.650. | G29: Extracted from the consolidated balance sheet; no cash flow statement values used.
A30: Credit institutions | B30: 6 | C30: 61513000 | D30: 55537000 | E30: 57917000 | F30: Banco Santander Consolidado 2025 2024.pdf; EURm x1,000 to EURk BS p.650. | G30: Extracted from the consolidated balance sheet; no cash flow statement values used.
A31: Customers | B31: 10 | C31: 985176000 | D31: 1011042000 | E31: 1009845000 | F31: Banco Santander Consolidado 2025 2024.pdf; EURm x1,000 to EURk BS p.650. | G31: Extracted from the consolidated balance sheet; no cash flow statement values used.
A32: Derivatives - hedge accounting | B32: 36 | C32: 3931000 | D32: 5672000 | E32: 5297000 | F32: Banco Santander Consolidado 2025 2024.pdf; EURm x1,000 to EURk BS p.650. | G32: Extracted from the consolidated balance sheet; no cash flow statement values used.
A33: Fair value changes of hedged items in portfolio hedge of interest rate risk | B33: 54 | C33: 50000 | D33: -704000 | E33: -788000 | F33: Banco Santander Consolidado 2025 2024.pdf; EURm x1,000 to EURk BS p.650. | G33: Extracted from the consolidated balance sheet; no cash flow statement values used.
A34: Investments in joint ventures and associates | B34: 13 | C34: 7052000 | D34: 7277000 | E34: 7646000 | F34: Banco Santander Consolidado 2025 2024.pdf; EURm x1,000 to EURk BS p.651. | G34: Extracted from the consolidated balance sheet; no cash flow statement values used.
A35: Joint ventures | C35: 1956000 | D35: 2061000 | E35: 1964000 | F35: Banco Santander Consolidado 2025 2024.pdf; EURm x1,000 to EURk BS p.651. | G35: Extracted from the consolidated balance sheet; no cash flow statement values used.
A36: Associates | C36: 5096000 | D36: 5216000 | E36: 5682000 | F36: Banco Santander Consolidado 2025 2024.pdf; EURm x1,000 to EURk BS p.651. | G36: Extracted from the consolidated balance sheet; no cash flow statement values used.
A37: Reinsurance contract assets | C37: 223000 | D37: 222000 | E37: 237000 | F37: Banco Santander Consolidado 2025 2024.pdf; EURm x1,000 to EURk BS p.651. | G37: Extracted from the consolidated balance sheet; no cash flow statement values used.
A38: Tangible assets | C38: 27438000 | D38: 32087000 | E38: 33882000 | F38: Banco Santander Consolidado 2025 2024.pdf; EURm x1,000 to EURk BS p.651. | G38: Extracted from the consolidated balance sheet; no cash flow statement values used.
A39: Property, plant and equipment | B39: 16 | C39: 26416000 | D39: 31212000 | E39: 32926000 | F39: Banco Santander Consolidado 2025 2024.pdf; EURm x1,000 to EURk BS p.651. | G39: Extracted from the consolidated balance sheet; no cash flow statement values used.
A40: For own use | C40: 11663000 | D40: 12636000 | E40: 13408000 | F40: Banco Santander Consolidado 2025 2024.pdf; EURm x1,000 to EURk BS p.651. | G40: Extracted from the consolidated balance sheet; no cash flow statement values used.
A41: Leased under operating leases | C41: 14753000 | D41: 18576000 | E41: 19518000 | F41: Banco Santander Consolidado 2025 2024.pdf; EURm x1,000 to EURk BS p.651. | G41: Extracted from the consolidated balance sheet; no cash flow statement values used.
...

Sheet Direct CF
A1: Banco Santander - Direct Cash Flow (Calculated Control View)
A2: Calculated from the P&L and balance sheet tabs only. The unreconciled balance is intentionally included inside the cash-flow bridge so ending cash reconciles to the balance sheet without using the published cash flow statement.
A4: Line item | B4: Formula type | C4: 2025 | D4: 2024 | E4: Source / input | F4: Control | G4: Methodology note
A5: Operating cash flow - source-backed accrual captions
A6: Interest income | B6: P&L link | C6: ='P&L'!C5 -> 101710000 | D6: ='P&L'!D5 -> 109012000 | E6: P&L | F6: Supportable accrual caption | G6: Direct cash receipts cannot be fully derived from P&L and balance sheet alone; this row uses reported accrual income.
A7: Interest expense | B7: P&L link | C7: ='P&L'!C9 -> -59362000 | D7: ='P&L'!D9 -> -65225000 | E7: P&L | F7: Supportable accrual caption | G7: Reported expense, not cash paid.
A8: Fee and commission income | B8: P&L link | C8: ='P&L'!C13 -> 17387000 | D8: ='P&L'!D13 -> 16834000 | E8: P&L | F8: Supportable accrual caption
A9: Fee and commission expense | B9: P&L link | C9: ='P&L'!C14 -> -4411000 | D9: ='P&L'!D14 -> -4458000 | E9: P&L | F9: Supportable accrual caption
A10: Other operating income less expenses | B10: Formula | C10: ='P&L'!C25+'P&L'!C26+'P&L'!C27+'P&L'!C28 -> -396000 | D10: ='P&L'!D25+'P&L'!D26+'P&L'!D27+'P&L'!D28 -> -1391000 | E10: P&L | F10: Supportable accrual caption
A11: Administrative expenses | B11: P&L link | C11: ='P&L'!C30 -> -21533000 | D11: ='P&L'!D30 -> -21970000 | E11: P&L | F11: Supportable accrual caption
A12: Tax expense/income from continuing operations | B12: P&L link | C12: ='P&L'!C47 -> -4723000 | D12: ='P&L'!D47 -> -4844000 | E12: P&L | F12: Supportable accrual caption
A13: Cash movement before unreconciled balance | B13: Formula | C13: =SUM(C6:C12) -> 28672000 | D13: =SUM(D6:D12) -> 27958000 | E13: Workbook formula | F13: Preliminary bridge | G13: This is deliberately not labelled CFO because direct cash receipts/payments are not available from the requested source set.
A14: Unreconciled balance included in cash flow | B14: Formula | C14: =('Balance Sheet'!C6-'Balance Sheet'!D6)-C13 -> -68599000 | D14: =('Balance Sheet'!D6-'Balance Sheet'!E6)-D13 -> -56092000 | E14: Workbook formula | F14: Included in ending balance | G14: Residual required to bridge source-backed accrual captions to the balance-sheet cash movement. This is part of total cash movement, not an external plug outside ending cash. It is not further reconciled because doing so would require cash-flow statement or note-level information outside the permitted source set.
A15: Total cash movement including unreconciled balance | B15: Formula | C15: =C13+C14 -> -39927000 | D15: =D13+D14 -> -28134000 | E15: Workbook formula | F15: Ties to Balance Sheet movement | G15: Includes the unreconciled balance as requested.
A16: Balance-sheet movement control
A17: Opening cash and demand deposits | B17: BS link | C17: ='Balance Sheet'!D6 -> 192208000 | D17: ='Balance Sheet'!E6 -> 220342000 | E17: Balance Sheet | F17: Cash opening balance
A18: Ending cash balance from direct cash flow | B18: Formula | C18: =C17+C15 -> 152281000 | D18: =D17+D15 -> 192208000 | E18: Workbook formula | F18: Calculated ending balance | G18: Opening cash plus total cash movement including unreconciled balance.
A19: Ending cash and demand deposits per balance sheet | B19: BS link | C19: ='Balance Sheet'!C6 -> 152281000 | D19: ='Balance Sheet'!D6 -> 192208000 | E19: Balance Sheet | F19: Cash ending balance
A20: Direct CF ending balance check | B20: Formula | C20: =C18-C19 -> 0 | D20: =D18-D19 -> 0 | E20: Workbook formula | F20: Should be zero | G20: Ending cash from direct cash flow must equal the balance sheet cash line.

Sheet Indirect CF
A1: Banco Santander - Indirect Cash Flow (Calculated from Net Income)
A2: Calculated from the P&L and balance sheet tabs only. The unreconciled balance is intentionally included inside the cash-flow bridge so ending cash reconciles to the balance sheet without using the published cash flow statement.
A4: Line item | B4: Formula type | C4: 2025 | D4: 2024 | E4: Source / input | F4: Control | G4: Methodology note
A5: Operating cash flow - indirect method
A6: Net income | B6: P&L link | C6: ='P&L'!C50 -> 15500000 | D6: ='P&L'!D50 -> 13744000 | E6: P&L | F6: Starting point | G6: Starts from net income, as requested.
A7: Add back: depreciation and amortisation | B7: P&L link | C7: =-'P&L'!C33 -> 3178000 | D7: =-'P&L'!D33 -> 3179000 | E7: P&L | F7: Non-cash addback proxy | G7: Uses P&L amortisation/depreciation caption.
A8: Add back: provisions or reversal of provisions | B8: P&L link | C8: =-'P&L'!C34 -> 2729000 | D8: =-'P&L'!D34 -> 3465000 | E8: P&L | F8: Non-cash addback proxy | G8: Classification may differ from statutory CFO without note-level cash information.
A9: Add back: impairment on financial assets | B9: P&L link | C9: =-'P&L'!C35 -> 12546000 | D9: =-'P&L'!D35 -> 12136000 | E9: P&L | F9: Non-cash addback proxy
A10: Add back: impairment on non-financial assets | B10: P&L link | C10: =-'P&L'!C39 -> 251000 | D10: =-'P&L'!D39 -> 624000 | E10: P&L | F10: Non-cash addback proxy
A11: Less: share of results of equity-accounted entities | B11: P&L link | C11: =-'P&L'!C12 -> -665000 | D11: =-'P&L'!D12 -> -687000 | E11: P&L | F11: Non-cash/subsidiary boundary proxy
A12: Working capital / operating balance-sheet movements - selected assets | B12: Formula | C12: =-SUM('Balance Sheet'!C37-'Balance Sheet'!D37,'Balance Sheet'!C46-'Balance Sheet'!D46,'Balance Sheet'!C49-'Balance Sheet'!D49) -> 359000 | D12: =-SUM('Balance Sheet'!D37-'Balance Sheet'!E37,'Balance Sheet'!D46-'Balance Sheet'!E46,'Balance Sheet'!D49-'Balance Sheet'!E49) -> 1106000 | E12: Balance Sheet | F12: Calculated movement | G12: Increase in selected operating assets is a use of cash.
A13: Working capital / operating balance-sheet movements - selected liabilities | B13: Formula | C13: =SUM('Balance Sheet'!C80-'Balance Sheet'!D80,'Balance Sheet'!C87-'Balance Sheet'!D87,'Balance Sheet'!C90-'Balance Sheet'!D90,'Balance Sheet'!C81-'Balance Sheet'!D81) -> 419000 | D13: =SUM('Balance Sheet'!D80-'Balance Sheet'!E80,'Balance Sheet'!D87-'Balance Sheet'!E87,'Balance Sheet'!D90-'Balance Sheet'!E90,'Balance Sheet'!D81-'Balance Sheet'!E81) -> -1592000 | E13: Balance Sheet | F13: Calculated movement | G13: Increase in selected operating liabilities is a source of cash.
A14: Calculated operating cash flow before classification gap | B14: Formula | C14: =SUM(C6:C13) -> 34317000 | D14: =SUM(D6:D13) -> 31975000 | E14: Workbook formula | F14: Subtotal
A15: Investing / financing / balance-sheet movement bridge
A16: Financial assets excluding cash | B16: Formula | C16: =-SUM('Balance Sheet'!C7-'Balance Sheet'!D7,'Balance Sheet'!C15-'Balance Sheet'!D15,'Balance Sheet'!C19-'Balance Sheet'!D19,'Balance Sheet'!C22-'Balance Sheet'!D22,'Balance Sheet'!C26-'Balance Sheet'!D26,'Balance Sheet'!C32-'Balance Sheet'!D32,'Balance Sheet'!C33-'Balance Sheet'!D33) -> -6536000 | D16: =-SUM('Balance Sheet'!D7-'Balance Sheet'!E7,'Balance Sheet'!D15-'Balance Sheet'!E15,'Balance Sheet'!D19-'Balance Sheet'!E19,'Balance Sheet'!D22-'Balance Sheet'!E22,'Balance Sheet'!D26-'Balance Sheet'!E26,'Balance Sheet'!D32-'Balance Sheet'!E32,'Balance Sheet'!D33-'Balance Sheet'!E33) -> -71047000 | E16: Balance Sheet | F16: Calculated movement | G16: Banking balance sheet movement; not force-classified into CFO/CFI.
A17: Investments in associates, tangible and intangible assets | B17: Formula | C17: =-SUM('Balance Sheet'!C34-'Balance Sheet'!D34,'Balance Sheet'!C38-'Balance Sheet'!D38,'Balance Sheet'!C43-'Balance Sheet'!D43) -> 6825000 | D17: =-SUM('Balance Sheet'!D34-'Balance Sheet'!E34,'Balance Sheet'!D38-'Balance Sheet'!E38,'Balance Sheet'!D43-'Balance Sheet'!E43) -> 2776000 | E17: Balance Sheet | F17: Calculated movement | G17: Includes non-cash and perimeter effects unless separately disclosed.
A18: Held-for-sale assets/liabilities net movement | B18: Formula | C18: =-('Balance Sheet'!C53-'Balance Sheet'!D53)+('Balance Sheet'!C91-'Balance Sheet'!D91) -> -8014000 | D18: =-('Balance Sheet'!D53-'Balance Sheet'!E53)+('Balance Sheet'!D91-'Balance Sheet'!E91) -> -988000 | E18: Balance Sheet | F18: Calculated movement | G18: Large 2025 movement is visible rather than manually normalised.
A19: Financial liabilities | B19: Formula | C19: =SUM('Balance Sheet'!C56-'Balance Sheet'!D56,'Balance Sheet'!C63-'Balance Sheet'!D63,'Balance Sheet'!C70-'Balance Sheet'!D70,'Balance Sheet'!C32-'Balance Sheet'!D32,'Balance Sheet'!C33-'Balance Sheet'!D33) -> -38942000 | D19: =SUM('Balance Sheet'!D56-'Balance Sheet'!E56,'Balance Sheet'!D63-'Balance Sheet'!E63,'Balance Sheet'!D70-'Balance Sheet'!E70,'Balance Sheet'!D32-'Balance Sheet'!E32,'Balance Sheet'!D33-'Balance Sheet'!E33) -> 41952000 | E19: Balance Sheet | F19: Calculated movement | G19: Increase in liabilities is a source of cash.
A20: Equity movement excluding current net income | B20: Formula | C20: =('Balance Sheet'!C117-'Balance Sheet'!D117)-'P&L'!C50 -> -10079000 | D20: =('Balance Sheet'!D117-'Balance Sheet'!E117)-'P&L'!D50 -> -10658000 | E20: Balance Sheet + P&L | F20: Calculated movement | G20: Keeps retained earnings and net income separate; includes dividends, OCI, buybacks, NCI and other equity movements.
A21: Cash movement before unreconciled balance | B21: Formula | C21: =C14+SUM(C16:C20) -> -22429000 | D21: =D14+SUM(D16:D20) -> -5990000 | E21: Workbook formula | F21: Preliminary bridge
A22: Unreconciled balance included in cash flow | B22: Formula | C22: =('Balance Sheet'!C6-'Balance Sheet'!D6)-C21 -> -17498000 | D22: =('Balance Sheet'!D6-'Balance Sheet'!E6)-D21 -> -22144000 | E22: Workbook formula | F22: Included in ending balance | G22: Residual required to bridge the calculated indirect cash flow to the balance-sheet cash movement. This is part of total cash movement, not an external plug outside ending cash.
A23: Total cash movement including unreconciled balance | B23: Formula | C23: =C21+C22 -> -39927000 | D23: =D21+D22 -> -28134000 | E23: Workbook formula | F23: Ties to Balance Sheet movement | G23: Includes the unreconciled balance as requested.
A24: Opening cash and demand deposits | B24: BS link | C24: ='Balance Sheet'!D6 -> 192208000 | D24: ='Balance Sheet'!E6 -> 220342000 | E24: Balance Sheet | F24: Cash opening balance
A25: Ending cash balance from indirect cash flow | B25: Formula | C25: =C24+C23 -> 152281000 | D25: =D24+D23 -> 192208000 | E25: Workbook formula | F25: Calculated ending balance | G25: Opening cash plus total cash movement including unreconciled balance.
A26: Ending cash and demand deposits per balance sheet | B26: BS link | C26: ='Balance Sheet'!C6 -> 152281000 | D26: ='Balance Sheet'!D6 -> 192208000 | E26: Balance Sheet | F26: Cash ending balance
A27: Indirect CF ending balance check | B27: Formula | C27: =C25-C26 -> 0 | D27: =D25-D26 -> 0 | E27: Workbook formula | F27: Should be zero | G27: Ending cash from indirect cash flow must equal the balance sheet cash line.

Sheet Checks
A1: Workbook Checks
A2: Formula-driven controls. PASS means the extracted statements and calculated tabs tie to their stated source/check logic; red rows identify source limitations or unreconciled balances.
A4: Check | B4: 2025 | C4: 2024 | D4: Tolerance | E4: Status | F4: Notes
A5: Balance sheet balances | B5: ='Balance Sheet'!C54-'Balance Sheet'!C118 -> 0 | C5: ='Balance Sheet'!D54-'Balance Sheet'!D118 -> 0 | D5: 0 | E5: =IF(AND(ABS(B5)<=D5,ABS(C5)<=D5),"PASS","REVIEW") -> PASS | F5: Total assets less total liabilities and equity.
A6: Equity detail ties to total equity | B6: ='Balance Sheet'!C94+'Balance Sheet'!C111+'Balance Sheet'!C114-'Balance Sheet'!C117 -> 0 | C6: ='Balance Sheet'!D94+'Balance Sheet'!D111+'Balance Sheet'!D114-'Balance Sheet'!D117 -> 0 | D6: 0 | E6: =IF(AND(ABS(B6)<=D6,ABS(C6)<=D6),"PASS","REVIEW") -> PASS | F6: Reported equity line compared with detailed equity line.
A7: Retained earnings separate from net income | B7: =0 -> 0 | C7: =0 -> 0 | D7: 0 | E7: =IF(AND(ABS(B7)<=D7,ABS(C7)<=D7),"PASS","REVIEW") -> PASS | F7: Retained earnings and current net income are separate source rows on Balance Sheet tab.
A8: P&L net income attributable tie-out | B8: ='P&L'!C50-'P&L'!C51-'P&L'!C52 -> 0 | C8: ='P&L'!D50-'P&L'!D51-'P&L'!D52 -> 0 | D8: 0 | E8: =IF(AND(ABS(B8)<=D8,ABS(C8)<=D8),"PASS","REVIEW") -> PASS | F8: Net income equals owners plus NCI.
A9: Direct CF ending balance ties to balance sheet | B9: ='Direct CF'!C20 -> 0 | C9: ='Direct CF'!D20 -> 0 | D9: 0 | E9: =IF(AND(ABS(B9)<=D9,ABS(C9)<=D9),"PASS","REVIEW") -> PASS | F9: Ending cash from Direct CF equals the balance sheet cash line after including unreconciled balance in total cash movement.
A10: Indirect CF ending balance ties to balance sheet | B10: ='Indirect CF'!C27 -> 0 | C10: ='Indirect CF'!D27 -> 0 | D10: 0 | E10: =IF(AND(ABS(B10)<=D10,ABS(C10)<=D10),"PASS","REVIEW") -> PASS | F10: Ending cash from Indirect CF equals the balance sheet cash line after including unreconciled balance in total cash movement.
A11: Direct unreconciled balance is included in cash movement | B11: ='Direct CF'!C15-'Direct CF'!C13-'Direct CF'!C14 -> 0 | C11: ='Direct CF'!D15-'Direct CF'!D13-'Direct CF'!D14 -> 0 | D11: 0 | E11: =IF(AND(ABS(B11)<=D11,ABS(C11)<=D11),"PASS","REVIEW") -> PASS | F11: Total cash movement equals preliminary direct bridge plus unreconciled balance.
A12: Indirect unreconciled balance is included in cash movement | B12: ='Indirect CF'!C23-'Indirect CF'!C21-'Indirect CF'!C22 -> 0 | C12: ='Indirect CF'!D23-'Indirect CF'!D21-'Indirect CF'!D22 -> 0 | D12: 0 | E12: =IF(AND(ABS(B12)<=D12,ABS(C12)<=D12),"PASS","REVIEW") -> PASS | F12: Total cash movement equals preliminary indirect bridge plus unreconciled balance.
A13: No manual cash-flow plug used | B13: 0 | C13: 0 | D13: 0 | E13: =IF(AND(ABS(B13)<=D13,ABS(C13)<=D13),"PASS","REVIEW") -> PASS | F13: No cash flow line is hardcoded to force a reconciliation.
A14: Source units converted to EUR thousands | B14: 1000 | C14: 1000 | D14: 1000 | E14: =IF(AND(ABS(B14)<=D14,ABS(C14)<=D14),"PASS","REVIEW") -> PASS | F14: Source PDF is EUR millions; workbook reports EUR thousands.
