Workbook

Sheet Summary
A1: Inditex - Consolidated P&L and Balance Sheet | B1: Inditex - Consolidated P&L and Balance Sheet | C1: Inditex - Consolidated P&L and Balance Sheet | D1: Inditex - Consolidated P&L and Balance Sheet | E1: Inditex - Consolidated P&L and Balance Sheet
A3: Company | B3: Industria de Diseno Textil, S.A. (Inditex)
A4: Index | B4: IBEX 35
A5: Fiscal year | B5: 2025
A6: Closing date | B6: 31/01/2026
A7: Currency / units | B7: EUR millions
A8: Source | B8: Consolidated annual accounts 2025; see Sources sheet
A10: This workbook summarizes Inditex's published consolidated P&L and balance sheet for fiscal year 2025. Figures are historical reported values, not projections. | B10: This workbook summarizes Inditex's published consolidated P&L and balance sheet for fiscal year 2025. Figures are historical reported values, not projections. | C10: This workbook summarizes Inditex's published consolidated P&L and balance sheet for fiscal year 2025. Figures are historical reported values, not projections. | D10: This workbook summarizes Inditex's published consolidated P&L and balance sheet for fiscal year 2025. Figures are historical reported values, not projections. | E10: This workbook summarizes Inditex's published consolidated P&L and balance sheet for fiscal year 2025. Figures are historical reported values, not projections.
A11: This workbook summarizes Inditex's published consolidated P&L and balance sheet for fiscal year 2025. Figures are historical reported values, not projections. | B11: This workbook summarizes Inditex's published consolidated P&L and balance sheet for fiscal year 2025. Figures are historical reported values, not projections. | C11: This workbook summarizes Inditex's published consolidated P&L and balance sheet for fiscal year 2025. Figures are historical reported values, not projections. | D11: This workbook summarizes Inditex's published consolidated P&L and balance sheet for fiscal year 2025. Figures are historical reported values, not projections. | E11: This workbook summarizes Inditex's published consolidated P&L and balance sheet for fiscal year 2025. Figures are historical reported values, not projections.
A12: This workbook summarizes Inditex's published consolidated P&L and balance sheet for fiscal year 2025. Figures are historical reported values, not projections. | B12: This workbook summarizes Inditex's published consolidated P&L and balance sheet for fiscal year 2025. Figures are historical reported values, not projections. | C12: This workbook summarizes Inditex's published consolidated P&L and balance sheet for fiscal year 2025. Figures are historical reported values, not projections. | D12: This workbook summarizes Inditex's published consolidated P&L and balance sheet for fiscal year 2025. Figures are historical reported values, not projections. | E12: This workbook summarizes Inditex's published consolidated P&L and balance sheet for fiscal year 2025. Figures are historical reported values, not projections.

Sheet P&L
A1: Consolidated P&L - Inditex | B1: Consolidated P&L - Inditex | C1: Consolidated P&L - Inditex | D1: Consolidated P&L - Inditex
A2: Fiscal year 2025. Figures in EUR millions. Source: Inditex consolidated annual accounts 2025. | B2: Fiscal year 2025. Figures in EUR millions. Source: Inditex consolidated annual accounts 2025. | C2: Fiscal year 2025. Figures in EUR millions. Source: Inditex consolidated annual accounts 2025. | D2: Fiscal year 2025. Figures in EUR millions. Source: Inditex consolidated annual accounts 2025.
A3: Fiscal year 2025. Figures in EUR millions. Source: Inditex consolidated annual accounts 2025. | B3: Fiscal year 2025. Figures in EUR millions. Source: Inditex consolidated annual accounts 2025. | C3: Fiscal year 2025. Figures in EUR millions. Source: Inditex consolidated annual accounts 2025. | D3: Fiscal year 2025. Figures in EUR millions. Source: Inditex consolidated annual accounts 2025.
A5: Line item | B5: 2025
A6: Net sales | B6: 39864
A7: Cost of sales | B7: -16642
A8: Gross profit | B8: =SUM(B6:B7) -> 23222
A9: Operating expenses | B9: -11878
A10: Other net income / expenses | B10: -77
A11: EBITDA | B11: =SUM(B8:B10) -> 11267
A12: Depreciation and amortization | B12: -3270
A13: EBIT | B13: =SUM(B11:B12) -> 7997
A14: Financial result | B14: -80
A15: Share of profit from equity-accounted companies | B15: 102
A16: Rounding adjustment to published EURm figures | B16: 1
A17: Profit before tax | B17: =SUM(B13:B16) -> 8020
A18: Income tax | B18: -1800
A19: Net income | B19: =SUM(B17:B18) -> 6220
A20: Net income attributable to the parent | B20: 6220
A22: Source | B22: See Sources sheet

Sheet Balance Sheet
A1: Consolidated Balance Sheet - Inditex | B1: Consolidated Balance Sheet - Inditex | C1: Consolidated Balance Sheet - Inditex | D1: Consolidated Balance Sheet - Inditex
A2: Comparative balance sheet as of 31/01/2026 and 31/01/2025. Figures in EUR millions. Source: Inditex consolidated annual accounts 2025. | B2: Comparative balance sheet as of 31/01/2026 and 31/01/2025. Figures in EUR millions. Source: Inditex consolidated annual accounts 2025. | C2: Comparative balance sheet as of 31/01/2026 and 31/01/2025. Figures in EUR millions. Source: Inditex consolidated annual accounts 2025. | D2: Comparative balance sheet as of 31/01/2026 and 31/01/2025. Figures in EUR millions. Source: Inditex consolidated annual accounts 2025.
A3: Comparative balance sheet as of 31/01/2026 and 31/01/2025. Figures in EUR millions. Source: Inditex consolidated annual accounts 2025. | B3: Comparative balance sheet as of 31/01/2026 and 31/01/2025. Figures in EUR millions. Source: Inditex consolidated annual accounts 2025. | C3: Comparative balance sheet as of 31/01/2026 and 31/01/2025. Figures in EUR millions. Source: Inditex consolidated annual accounts 2025. | D3: Comparative balance sheet as of 31/01/2026 and 31/01/2025. Figures in EUR millions. Source: Inditex consolidated annual accounts 2025.
A5: Assets | B5: 2025 | D5: 2024
A6: Non-current assets | B6: 19947 | D6: 18358
A7: Right-of-use assets | B7: 5542 | D7: 5269
A8: Other intangible assets | B8: 1643 | D8: 1411
A9: Goodwill | B9: 197 | D9: 196
A10: Property, plant and equipment | B10: 11135 | D10: 10005
A11: Investment property | B11: 6 | D11: 9
A12: Financial investments | B12: 471 | D12: 450
A13: Other non-current assets | B13: 203 | D13: 217
A14: Deferred tax assets | B14: 750 | D14: 800
A15: Current assets | B15: 15691 | D15: 16356
A16: Inventories | B16: 3249 | D16: 3321
A17: Trade and other receivables | B17: 1166 | D17: 1088
... A23: Total assets | B23: 35638 | D23: 34714
A25: Equity and liabilities
A26: Equity | B26: 20395 | D26: 19676
A27: Equity attributable to the parent | B27: 20395 | D27: 19676
A28: Non-controlling interests | B28: 0 | D28: 0
A30: Equity detail | B30: 2025 | D30: 2024
A31: Share capital | B31: 94 | D31: 94
A32: Share premium | B32: 20 | D32: 20
A33: Retained earnings | B33: 13605 | D33: 13128
A34: Profit for the year | B34: 6220 | D34: 5866
A35: Other reserves | B35: 624 | D35: 571
A36: Reserves of equity-accounted companies | B36: 338 | D36: 329
A37: Treasury shares | B37: -7 | D37: -47
A38: Translation differences | B38: -490 | D38: -290
A39: Cash flow hedges | B39: -9 | D39: 5
A40: Equity detail check | B40: =SUM(B31:B39)-B27 -> 0 | D40: 0
A42: Liabilities | B42: 2025 | D42: 2024
A43: Non-current liabilities | B43: 5071 | D43: 4851
A44: Provisions | B44: 345 | D44: 348
A45: Other non-current liabilities | B45: 231 | D45: 251
A46: Financial debt | B46: 0 | D46: 0
A47: Non-current lease liabilities | B47: 4394 | D47: 4180
A48: Deferred tax liabilities | B48: 101 | D48: 72
A49: Current liabilities | B49: 10172 | D49: 10187
...

Sheet Cash Flow - Direct
A1: Calculated Cash Flow - Direct Method | B1: Calculated Cash Flow - Direct Method | C1: Calculated Cash Flow - Direct Method | D1: Calculated Cash Flow - Direct Method
A2: Formula-driven full cash flow statement. Direct operating cash flows reconcile to CFO, then to ending cash through investing, financing and FX. | B2: Formula-driven full cash flow statement. Direct operating cash flows reconcile to CFO, then to ending cash through investing, financing and FX. | C2: Formula-driven full cash flow statement. Direct operating cash flows reconcile to CFO, then to ending cash through investing, financing and FX. | D2: Formula-driven full cash flow statement. Direct operating cash flows reconcile to CFO, then to ending cash through investing, financing and FX.
A3: Formula-driven full cash flow statement. Direct operating cash flows reconcile to CFO, then to ending cash through investing, financing and FX. | B3: Formula-driven full cash flow statement. Direct operating cash flows reconcile to CFO, then to ending cash through investing, financing and FX. | C3: Formula-driven full cash flow statement. Direct operating cash flows reconcile to CFO, then to ending cash through investing, financing and FX. | D3: Formula-driven full cash flow statement. Direct operating cash flows reconcile to CFO, then to ending cash through investing, financing and FX.
A5: Line item | B5: 2025
A6: Cash receipts from customers | B6: ='P&L'!B6-('Balance Sheet'!B17-'Balance Sheet'!D17) -> 39786
A7: Cash paid to suppliers/vendors and operating expenses | B7: ='Cash Flow - Indirect'!B19-B6-B9 -> -28969
A8: Cash generated from operations before tax | B8: =SUM(B6:B7) -> 10817
A9: Income taxes paid | B9: -1585
A10: Net cash from operating activities | B10: =SUM(B8:B9) -> 9232
A12: Purchases of PPE and intangible assets | B12: -2712
A13: Investments in companies | B13: -16
A14: Other investing items | B14: 58
A15: Change in current financial investments | B15: -545
A16: Net cash used in investing activities | B16: =SUM(B12:B15) -> -3215
A18: Change in short-term borrowings | B18: ='Balance Sheet'!B50-'Balance Sheet'!D50 -> -5
A19: Lease principal payments | B19: -1834
A20: Dividends paid | B20: -5236
A21: Net cash used in financing activities | B21: =SUM(B18:B20) -> -7075
A23: Net change in cash before FX | B23: =SUM(B10,B16,B21) -> -1058
A24: FX / other cash movement | B24: -48
A25: Net change in cash | B25: =SUM(B23:B24) -> -1106
A26: Opening cash and cash equivalents | B26: ='Balance Sheet'!D22 -> 6382
A27: Cash and cash equivalents at end of period | B27: =SUM(B25:B26) -> 5276
A28: Reported closing cash and cash equivalents | B28: ='Balance Sheet'!B22 -> 5276
A29: Cash flow check | B29: =B27-B28 -> 0
A30: Direct vs indirect CFO check | B30: =B10-'Cash Flow - Indirect'!B19 -> 0
A35: Note: The supplier/vendor and operating payment line is calculated as the residual operating cash payment after customer receipts and taxes, because the published summary accounts do not disclose every transactional operating cash payment separately. | B35: Note: The supplier/vendor and operating payment line is calculated as the residual operating cash payment after customer receipts and taxes, because the published summary accounts do not disclose every transactional operating cash payment separately. | C35: Note: The supplier/vendor and operating payment line is calculated as the residual operating cash payment after customer receipts and taxes, because the published summary accounts do not disclose every transactional operating cash payment separately. | D35: Note: The supplier/vendor and operating payment line is calculated as the residual operating cash payment after customer receipts and taxes, because the published summary accounts do not disclose every transactional operating cash payment separately.
A36: Source: See Sources sheet | B36: Source: See Sources sheet | C36: Source: See Sources sheet | D36: Source: See Sources sheet

Sheet Cash Flow - Indirect
A1: Calculated Cash Flow - Indirect Method | B1: Calculated Cash Flow - Indirect Method | C1: Calculated Cash Flow - Indirect Method | D1: Calculated Cash Flow - Indirect Method
A2: Formula-driven full indirect cash flow statement. Closing cash is reconciled to the balance sheet. | B2: Formula-driven full indirect cash flow statement. Closing cash is reconciled to the balance sheet. | C2: Formula-driven full indirect cash flow statement. Closing cash is reconciled to the balance sheet. | D2: Formula-driven full indirect cash flow statement. Closing cash is reconciled to the balance sheet.
A3: Formula-driven full indirect cash flow statement. Closing cash is reconciled to the balance sheet. | B3: Formula-driven full indirect cash flow statement. Closing cash is reconciled to the balance sheet. | C3: Formula-driven full indirect cash flow statement. Closing cash is reconciled to the balance sheet. | D3: Formula-driven full indirect cash flow statement. Closing cash is reconciled to the balance sheet.
A5: Line item | B5: 2025
A6: Net income | B6: ='P&L'!B19 -> 6220
A7: Depreciation and amortization | B7: =-'P&L'!B12 -> 3270
A8: Financial result add-back | B8: =-'P&L'!B14 -> 80
A9: Share of profit from equity-accounted companies | B9: =-'P&L'!B15 -> -102
A10: Income tax expense add-back | B10: =-'P&L'!B18 -> 1800
A11: Other operating adjustments | B11: 147
A12: Operating cash flow before tax and working capital | B12: =SUM(B6:B11) -> 11415
A13: Income taxes paid | B13: -1585
A14: Change in inventories | B14: =-('Balance Sheet'!B16-'Balance Sheet'!D16) -> 72
A15: Change in trade and other receivables | B15: =-('Balance Sheet'!B17-'Balance Sheet'!D17) -> -78
A16: Change in other current assets | B16: 71
A17: Change in trade and other payables | B17: -663
A18: Change in working capital | B18: =SUM(B14:B17) -> -598
A19: Net cash from operating activities | B19: =SUM(B12:B13,B18) -> 9232
A21: Purchases of PPE and intangible assets | B21: -2712
A22: Investments in companies | B22: -16
A23: Other investing items | B23: 58
A24: Change in current financial investments | B24: -545
A25: Net cash used in investing activities | B25: =SUM(B21:B24) -> -3215
A27: Change in short-term borrowings | B27: ='Balance Sheet'!B50-'Balance Sheet'!D50 -> -5
A28: Lease principal payments | B28: -1834
A29: Dividends paid | B29: -5236
A30: Net cash used in financing activities | B30: =SUM(B27:B29) -> -7075
A32: Net change in cash before FX | B32: =SUM(B19,B25,B30) -> -1058
A33: FX / other cash movement | B33: -48
A34: Net change in cash | B34: =SUM(B32:B33) -> -1106
A35: Opening cash and cash equivalents | B35: ='Balance Sheet'!D22 -> 6382
A36: Calculated closing cash and cash equivalents | B36: =SUM(B34:B35) -> 5276
A37: Reported closing cash and cash equivalents | B37: ='Balance Sheet'!B22 -> 5276
A38: Cash flow check | B38: =B36-B37 -> 0
A40: Note: Certain investing and financing lines are shown directly in this statement because they cannot be derived cleanly from a summarized balance sheet alone. | B40: Note: Certain investing and financing lines are shown directly in this statement because they cannot be derived cleanly from a summarized balance sheet alone. | C40: Note: Certain investing and financing lines are shown directly in this statement because they cannot be derived cleanly from a summarized balance sheet alone. | D40: Note: Certain investing and financing lines are shown directly in this statement because they cannot be derived cleanly from a summarized balance sheet alone.
A41: Source: See Sources sheet | B41: Source: See Sources sheet | C41: Source: See Sources sheet | D41: Source: See Sources sheet

Sheet Sources
A1: Sources and Audit Notes | B1: Sources and Audit Notes | C1: Sources and Audit Notes | D1: Sources and Audit Notes
A3: Item | B3: Period / date | C3: Source | D3: Notes
A4: Consolidated P&L | B4: 2025 | C4: https://www.inditex.com/itxcomweb/api/media/50ba1fc0-3862-4408-8da2-4f973f1be18e/AnnualAccountsDirectorsReportandAuditReportconsolidated.pdf?t=1773650991401 | D4: Amounts reported by Inditex in EUR millions.
A5: Balance sheet and cash flow statement | B5: 2025 and 2024 | C5: https://www.inditex.com/itxcomweb/api/media/50ba1fc0-3862-4408-8da2-4f973f1be18e/AnnualAccountsDirectorsReportandAuditReportconsolidated.pdf?t=1773650991401 | D5: Used for balance sheet, working capital movements, investing, financing, FX and ending cash reconciliation.
