Workbook

Sheet P&L
A1: Repsol, S.A. and Investees Comprising the Repsol Group
A2: Consolidated Income Statement — Years ended December 31, 2025 and 2024 (€ thousand, unless otherwise stated)
A4: Line item | B4: Note | C4: FY2025 | D4: FY2024
A5: Sales | C5: 54421000 | D5: 56713000
A6: Income from services rendered and other income | C6: 440000 | D6: 409000
A7: Changes in inventories of finished goods and work in progress | B7: 5.2 | C7: 69000 | D7: -225000
A8: Procurements | B8: 5.3 | C8: -41300000 | D8: -42234000
A9: Amortization and depreciation of non-current assets | B9: 16, 17 | C9: -2439000 | D9: -2932000
A10: (Charges for)/Reversal of impairment | B10: 5.4, 6 | C10: 1000 | D10: -946000
A11: Personnel expenses | B11: 5.5 | C11: -2178000 | D11: -2199000
A12: Transport and freight | C12: -1648000 | D12: -1784000
A13: Supplies | C13: -654000 | D13: -663000
A14: Gains/(Losses) on disposal and derecognition of assets | B14: 5.7 | C14: 14000 | D14: 2000
A15: Other operating income/(expenses) | B15: 5.8 | C15: -4017000 | D15: -4196000
A17: OPERATING INCOME/(LOSS) | C17: =SUM(C5:C15) -> 2709000 | D17: =SUM(D5:D15) -> 1945000
A19: Interest income | C19: 257000 | D19: 341000
A20: Interest expenses | C20: -291000 | D20: -303000
A21: Change in fair value of financial instruments | C21: -298000 | D21: 220000
A22: Exchange gains/(losses) | C22: 468000 | D22: -271000
A23: (Provision for)/Reversal of impairment of financial instruments | C23: 25000 | D23: -43000
A24: Other financial income and expenses | C24: -106000 | D24: -156000
A26: FINANCIAL RESULT | C26: =SUM(C19:C24) -> 55000 | D26: =SUM(D19:D24) -> -212000
A28: Net income from investments accounted for using the equity method | B28: 18 | C28: 53000 | D28: 439000
A30: NET INCOME/(LOSS) BEFORE TAX | C30: =C17+C26+C28 -> 2817000 | D30: =D17+D26+D28 -> 2172000
A32: Income tax | B32: 8 | C32: -717000 | D32: -562000
A34: CONSOLIDATED NET INCOME/(LOSS) FOR THE PERIOD | C34: =C30+C32 -> 2100000 | D34: =D30+D32 -> 1610000
A36: Net income attributable to non-controlling interests | B36: 11 | C36: -201000 | D36: 146000
A38: TOTAL NET INCOME ATTRIBUTABLE TO THE PARENT | C38: =C34+C36 -> 1899000 | D38: =D34+D36 -> 1756000
A40: Earnings per share attributable to the parent (€/share — not in € thousand)
A41: Basic | B41: 9 | C41: 1.62 | D41: 1.43
A42: Diluted | B42: 9 | C42: 1.62 | D42: 1.43
A44: Source: Repsol Group Consolidated Financial Statements at December 31, 2025 (audited), Income Statement p.2 and related notes. Figures translated from € million as originally presented (× 1,000). Free translation of a report originally issued in Spanish; in the event of a discrepancy the Spanish version prevails.

Sheet Balance Sheet
A1: Repsol, S.A. and Investees Comprising the Repsol Group
A2: Consolidated Balance Sheet — At December 31, 2025 and 2024 (€ thousand)
A4: Line item | B4: Note | C4: 12/31/2025 | D4: 12/31/2024
A5: ASSETS
A6: Intangible assets | B6: 16 | C6: 2920000 | D6: 3125000
A7: Property, plant and equipment | B7: 17 | C7: 25652000 | D7: 27977000
A8: Investments accounted for using the equity method | B8: 18 | C8: 3721000 | D8: 3186000
A9: Non-current financial assets | B9: 13 | C9: 1000000 | D9: 1533000
A10: Deferred tax assets | B10: 8 | C10: 3368000 | D10: 4405000
A11: Other non-current assets | B11: 19 | C11: 1394000 | D11: 1696000
A13: NON-CURRENT ASSETS | C13: =SUM(C6:C11) -> 38055000 | D13: =SUM(D6:D11) -> 41922000
A15: Non-current assets held for sale | B15: 19 | C15: 1227000 | D15: 524000
A16: Inventories | B16: 21 | C16: 5475000 | D16: 6211000
A17: Trade and other receivables | B17: 22 | C17: 6557000 | D17: 7364000
A18: Other current assets | B18: 19 | C18: 135000 | D18: 296000
A19: Other current financial assets | B19: 13 | C19: 4718000 | D19: 2111000
A20: Cash and cash equivalents | B20: 13 | C20: 3261000 | D20: 4758000
A22: CURRENT ASSETS | C22: =SUM(C15:C20) -> 21373000 | D22: =SUM(D15:D20) -> 21264000
A23: TOTAL ASSETS | C23: =C13+C22 -> 59428000 | D23: =D13+D22 -> 63186000
A25: EQUITY AND LIABILITIES
A26: Shareholders' equity
A27: Share capital | B27: 11.1 | C27: 1105000 | D27: 1157000
A28: Share premium | B28: 11 | C28: 4038000 | D28: 4038000
A29: Legal reserve | B29: 11 | C29: 221000 | D29: 235000
A30: Other reserves (retained earnings) | B30: 11 | C30: 16348000 | D30: 16437000
A31: Interim dividends and remuneration | B31: 11.3 | C31: 0 | D31: -29000
A32: Treasury shares | B32: 11.2 | C32: -3000 | D32: -2000
A33: Net income for the period attributable to the parent | C33: 1899000 | D33: 1756000
A34: Other equity instruments (perpetual subordinated bonds) | B34: 11.4 | C34: 3046000 | D34: 2291000
A36: Shareholders' equity | C36: =SUM(C27:C34) -> 26654000 | D36: =SUM(D27:D34) -> 25883000
A38: Other cumulative comprehensive income
A39: Equity instruments through other comprehensive income | B39: 11 | C39: -18000 | D39: -22000
A40: Hedging transactions | B40: 11 | C40: -446000 | D40: -394000
A41: Translation differences | B41: 11 | C41: -1050000 | D41: 1022000
A43: Other cumulative comprehensive income | C43: =SUM(C39:C41) -> -1514000 | D43: =SUM(D39:D41) -> 606000
A45: Non-controlling interests | B45: 11.5 | C45: 2478000 | D45: 2610000
A47: TOTAL EQUITY | C47: =C36+C43+C45 -> 27618000 | D47: =D36+D43+D45 -> 29099000
A49: Non-current provisions | B49: 20 | C49: 3002000 | D49: 5137000
A50: Non-current financial liabilities | B50: 12 | C50: 11410000 | D50: 9433000
A51: Deferred tax liabilities and other tax items | B51: 8 | C51: 2419000 | D51: 2658000
...

Sheet Indirect CF
A1: Repsol, S.A. and Investees Comprising the Repsol Group
A2: Consolidated Statement of Cash Flows — Indirect Method — Year ended December 31, 2025 (€ thousand)
A3: Independently derived by the analyst from the Group's audited Income Statement, Balance Sheet and Statement of Changes in Equity (FY2024 vs FY2025) plus selected explanatory notes (Notes 6, 11, 16, 17, 18 and 20). It does NOT reproduce, and was not derived from, Repsol's own published Statement of Cash Flows. Methodology: full balance-sheet-reconciliation (indirect) method — every balance sheet caption is mapped to operating, investing or financing activities, so the statement below ties exactly, line for line, to the actual reported movement in cash (no manual balancing entries).
A6: Line item | B6: Note | C6: FY2025 | D6: Amount
A7: SUPPORTING DATA SOURCED FROM NOTES (not derivable from P&L / Balance Sheet tabs alone)
A8: Net reversal of impairment losses on PP&E and intangible assets, net (2025) | B8: Note 6 / 5.4 | C8: 198000
A9: Dividends received from investments accounted for using the equity method | B9: Note 18 | C9: 93000
A10: Dividends paid to shareholders of the parent | B10: Note 11.3 | C10: 1131000
A11: Dividends paid to non-controlling interests | B11: Note 11.5 | C11: 257000
A12: Purchases of treasury shares, net (market purchases less sales) | B12: Note 11.2 / SOCE | C12: 691000
A13: Proceeds from issuance of subordinated perpetual bonds (equity instruments) | B13: Note 11.4 | C13: 1500000
A14: Repurchase and redemption of subordinated perpetual bonds | B14: Note 11.4 | C14: 758000
A15: Coupon paid on subordinated perpetual bonds, net of tax | B15: Note 11.4 | C15: 67000
A16: Capital contributions from non-controlling interests | B16: Note 11.5 | C16: 97000
A18: Blue = hardcoded input sourced from a specific note (see column B). Black = formula linked to the P&L / Balance Sheet tabs.
A20: CASH FLOWS FROM OPERATING ACTIVITIES
A21: Consolidated net income for the period | C21: ='P&L'!C34 -> 2100000 | D21: Per P&L tab: Consolidated net income (2025)
A22: Adjustments for non-cash items:
A23: Amortization and depreciation of non-current assets | C23: =-'P&L'!C9 -> 2439000
A24: Net reversal of impairment losses on PP&E and intangible assets (non-cash) | C24: =-C8 -> -198000
A25: Net gain on disposal of non-current assets (non-cash) | C25: =-'P&L'!C14 -> -14000
A26: Result from investments accounted for using the equity method (non-cash) | C26: =-'P&L'!C28 -> -53000
A27: Dividends received from investments accounted for using the equity method | C27: =C9 -> 93000
A28: Net movement in deferred tax assets | C28: =-('Balance Sheet'!C10-'Balance Sheet'!D10) -> 1037000
A29: Net movement in deferred tax liabilities and other tax items | C29: ='Balance Sheet'!C51-'Balance Sheet'!D51 -> -239000
A30: Net movement in non-current provisions | C30: ='Balance Sheet'!C49-'Balance Sheet'!D49 -> -2135000
A31: Net movement in current provisions | C31: ='Balance Sheet'!C57-'Balance Sheet'!D57 -> -337000
A32: Net movement in other non-current assets | C32: =-('Balance Sheet'!C11-'Balance Sheet'!D11) -> 302000
A33: Net movement in other non-current liabilities | C33: ='Balance Sheet'!C52-'Balance Sheet'!D52 -> -77000
A35: Changes in working capital:
A36: (Increase)/decrease in inventories | C36: =-('Balance Sheet'!C16-'Balance Sheet'!D16) -> 736000
A37: (Increase)/decrease in trade and other receivables | C37: =-('Balance Sheet'!C17-'Balance Sheet'!D17) -> 807000
A38: (Increase)/decrease in other current assets | C38: =-('Balance Sheet'!C18-'Balance Sheet'!D18) -> 161000
A39: Increase/(decrease) in trade and other payables | C39: ='Balance Sheet'!C59-'Balance Sheet'!D59 -> -1001000
A41: NET CASH FLOWS FROM OPERATING ACTIVITIES (I) | C41: =C21+SUM(C22:C39) -> 3621000
A43: CASH FLOWS FROM INVESTING ACTIVITIES
A44: Net investment in PP&E and intangible assets (net of disposals, translation differences and portfolio/scope changes) | C44: =(-('Balance Sheet'!C6-'Balance Sheet'!D6)-('Balance Sheet'!C7-'Balance Sheet'!D7)) - ((-'P&L'!C9)-C8-'P&L'!C14) -> 303000
A45: Net investment in investments accounted for using the equity method (net of income and dividends already reflected in operating activities) | C45: =(-('Balance Sheet'!C8-'Balance Sheet'!D8)) - ((-'P&L'!C28)+C9) -> -575000
A46: Net collection/(disbursement) of non-current financial assets | C46: =-('Balance Sheet'!C9-'Balance Sheet'!D9) -> 533000
A47: Net (purchases)/maturities of other current financial assets (money-market funds, deposits) | C47: =-('Balance Sheet'!C19-'Balance Sheet'!D19) -> -2607000
...

Sheet Direct CF
A1: Repsol, S.A. and Investees Comprising the Repsol Group
A2: Consolidated Statement of Cash Flows — Direct Method — Year ended December 31, 2025 (€ thousand)
A3: Independently derived (not taken from Repsol's published Statement of Cash Flows). Under IAS 7, the direct and indirect methods produce an IDENTICAL total for operating, investing and financing activities — only the presentation of the operating section differs. Cash receipts/payments below are estimated by converting the accrual-basis Income Statement captions to a cash basis using the working-capital movements on the Balance Sheet; investing and financing activities are linked directly to the 'Indirect CF' tab, which is unchanged between the two methods.
A6: Line item | B6: Note | C6: FY2025
A7: CASH FLOWS FROM OPERATING ACTIVITIES
A8: Cash received from customers | C8: ='P&L'!C5+'P&L'!C6-('Balance Sheet'!C17-'Balance Sheet'!D17) -> 55668000
A9: Cash paid to suppliers | C9: ='P&L'!C8-('Balance Sheet'!C16-'Balance Sheet'!D16)+('Balance Sheet'!C59-'Balance Sheet'!D59) -> -41565000
A10: Cash paid to employees | C10: ='P&L'!C11 -> -2178000
A11: Cash paid for transport and freight | C11: ='P&L'!C12 -> -1648000
A12: Cash paid for supplies | C12: ='P&L'!C13 -> -654000
A13: Dividends received from investments accounted for using the equity method | C13: ='Indirect CF'!C27 -> 93000
A14: Net movement in deferred tax assets and liabilities | C14: ='Indirect CF'!C28+'Indirect CF'!C29 -> 798000
A15: Net movement in provisions (non-current and current) | C15: ='Indirect CF'!C30+'Indirect CF'!C31 -> -2472000
A16: Net movement in other non-current assets and liabilities | C16: ='Indirect CF'!C32+'Indirect CF'!C33 -> 225000
A17: Net movement in other current assets | C17: ='Indirect CF'!C38 -> 161000
A18: Other operating cash payments, net (services, leases, taxes other than income tax, repairs, CO2 costs, and other reconciling operating items — see Indirect CF tab) | C18: ='Indirect CF'!C41-(C8+C9+C10+C11+C12+C13+C14+C15+C16+C17) -> -4807000
A20: NET CASH FLOWS FROM OPERATING ACTIVITIES (I) | C20: =SUM(C8:C18) -> 3621000
A22: Check: Direct-method operating cash flow vs. Indirect-method operating cash flow (must be zero) | C22: =C20-'Indirect CF'!C41 -> 0
A24: CASH FLOWS FROM INVESTING ACTIVITIES (identical to Indirect CF tab — IAS 7 only permits a choice of method for operating activities)
A25: Net investment in PP&E and intangible assets (net of disposals, translation differences and portfolio/scope changes) | C25: ='Indirect CF'!C44 -> 303000
A26: Net investment in investments accounted for using the equity method (net of income and dividends already reflected in operating activities) | C26: ='Indirect CF'!C45 -> -575000
A27: Net collection/(disbursement) of non-current financial assets | C27: ='Indirect CF'!C46 -> 533000
A28: Net (purchases)/maturities of other current financial assets (money-market funds, deposits) | C28: ='Indirect CF'!C47 -> -2607000
A29: Net movement in non-current assets held for sale (reclassification, largely non-cash — see note) | C29: ='Indirect CF'!C48 -> -703000
A31: NET CASH FLOWS FROM INVESTING ACTIVITIES (II) | C31: =SUM(C25:C29) -> -3049000
A33: CASH FLOWS FROM FINANCING ACTIVITIES (identical to Indirect CF tab)
A34: Dividends paid to shareholders of the parent | C34: ='Indirect CF'!C53 -> -1131000
A35: Dividends paid to non-controlling interests | C35: ='Indirect CF'!C54 -> -257000
A36: Purchases of treasury shares, net | C36: ='Indirect CF'!C55 -> -691000
A37: Capital contributions from non-controlling interests | C37: ='Indirect CF'!C56 -> 97000
A38: Proceeds from issuance of subordinated perpetual bonds | C38: ='Indirect CF'!C57 -> 1500000
A39: Repurchase and redemption of subordinated perpetual bonds | C39: ='Indirect CF'!C58 -> -758000
A40: Coupon paid on subordinated perpetual bonds, net of tax | C40: ='Indirect CF'!C59 -> -67000
A41: Other equity movements, net (non-cash reserve reclassifications, NCI ownership-change effects and other items per the Statement of Changes in Equity, net of amounts shown above) | C41: ='Indirect CF'!C60 -> -154000
A42: Other comprehensive income movements (translation differences, hedges, equity instruments at FVOCI — non-cash) | C42: ='Indirect CF'!C61 -> -2120000
A43: Net movement in non-current financial liabilities | C43: ='Indirect CF'!C62 -> 1977000
A44: Net movement in current financial liabilities | C44: ='Indirect CF'!C63 -> -927000
A45: Net movement in liabilities associated with non-current assets held for sale | C45: ='Indirect CF'!C64 -> 462000
A47: NET CASH FLOWS FROM FINANCING ACTIVITIES (III) | C47: =SUM(C34:C45) -> -2069000
A49: NET INCREASE/(DECREASE) IN CASH AND CASH EQUIVALENTS (I + II + III) | C49: =C20+C31+C47 -> -1497000
...
