Workbook

Sheet P&L
A1: Repsol Consolidated Income Statement
A2: EUR thousands, no decimals. Source PDF figures in EUR millions multiplied by 1,000.
A4: Line item | B4: 2025 | C4: 2024 | D4: Source / audit note
A5: Sales | B5: 54421000 | C5: 56713000 | D5: Income statement, PDF p. 14
A6: Income from services rendered and other income | B6: 440000 | C6: 409000 | D6: Income statement, PDF p. 14
A7: Changes in inventories of finished goods and work in progress | B7: 69000 | C7: -225000 | D7: Income statement, PDF p. 14
A8: Procurements | B8: -41300000 | C8: -42234000 | D8: Income statement, PDF p. 14
A9: Amortization and depreciation of non-current assets | B9: -2439000 | C9: -2932000 | D9: Income statement, PDF p. 14
A10: (Charges for)/Reversal of impairment | B10: 1000 | C10: -946000 | D10: Income statement, PDF p. 14
A11: Personnel expenses | B11: -2178000 | C11: -2199000 | D11: Income statement, PDF p. 14
A12: Transport and freights | B12: -1648000 | C12: -1784000 | D12: Income statement, PDF p. 14
A13: Supplies | B13: -654000 | C13: -663000 | D13: Income statement, PDF p. 14
A14: Gains/(Losses) on disposal and derecognition of assets | B14: 14000 | C14: 2000 | D14: Income statement, PDF p. 14
A15: Other operating income/(expenses) | B15: -4017000 | C15: -4196000 | D15: Income statement, PDF p. 14
A16: OPERATING INCOME/(LOSS) | B16: 2709000 | C16: 1945000 | D16: Income statement, PDF p. 14
... A29: TOTAL NET INCOME ATTRIBUTABLE TO THE PARENT | B29: 1899000 | C29: 1756000 | D29: Income statement, PDF p. 14
A31: Memo: EPS shown in EUR/share, not EUR thousands
A32: Basic EPS attributable to the parent (EUR/share) | B32: 1.62 | C32: 1.43 | D32: Income statement, PDF p. 14
A33: Diluted EPS attributable to the parent (EUR/share) | B33: 1.62 | C33: 1.43 | D33: Income statement, PDF p. 14

Sheet Balance Sheet
A1: Repsol Consolidated Balance Sheet | K1: Source-backed cash flow support | P1: Repsol Cash Flow Statement - Direct Method | U1: Repsol Cash Flow Statement - Indirect Method
A2: EUR thousands, no decimals. Equity is expanded using the statement of changes in equity; retained earnings/reserves are separated from net income. | K2: Support data used by cash flow formulas; the published cash flow statement was not used as an input. | P2: Reconstructed from P&L, balance sheet, equity roll-forward and selected source notes; the published cash flow statement was not used. | U2: Reconstructed from P&L, balance sheet, equity roll-forward and selected source notes; the published cash flow statement was not used.
A4: Line item | B4: 12/31/2025 | C4: 12/31/2024 | D4: Source / audit note | K4: Line item | L4: 2025 | M4: Source / logic | N4: Technical treatment | P4: Line item | Q4: 2025 | R4: Formula / source logic | S4: Technical note | U4: Line item | V4: 2025 | W4: Formula / source logic | X4: Technical note
A5: ASSETS | K5: PPE investments | L5: 3608000 | M5: Note 17, PDF p. 69 | N5: Gross investments in property, plant and equipment. | P5: Beginning cash and cash equivalents | R5: Prior-year balance sheet cash | U5: Beginning cash and cash equivalents | W5: Prior-year balance sheet cash
A6: Intangible assets | B6: 2920000 | C6: 3125000 | D6: Balance sheet, PDF p. 16 | K6: Intangible investments | L6: 254000 | M6: Note 16, PDF p. 67 | N6: Gross investments in other intangible assets. | P6: Cash flow from operating activities - direct method | U6: Cash flow from operating activities - indirect method
A7: Property, plant and equipment | B7: 25652000 | C7: 27977000 | D7: Balance sheet, PDF p. 16 | K7: New lease registrations/cancellations | L7: 251000 | M7: Note 17, PDF p. 71 | N7: Non-cash lease additions excluded from cash capex proxy. | P7: Cash receipts from customers | R7: Sales + services/other income - increase in trade receivables | S7: Uses trade and other receivables because customer receivables are not separately disclosed in the balance sheet. | U7: Consolidated net income | W7: Starts from net income, per user request
A8: Investments accounted for using the equity method | B8: 3721000 | C8: 3186000 | D8: Balance sheet, PDF p. 16 | K8: Cash capex proxy | L8: =L5+L6-L7 -> 3611000 | M8: Formula: PPE + intangibles - new leases | N8: Proxy because the note states PPE investments include lease additions. | P8: Cash paid to suppliers and other operating costs | R8: Procurements + transport + supplies + other opex - inventory increase + payables increase | S8: Trade payables are not separately disclosed; this uses the reported trade and other payables line. | U8: Add back: amortization and depreciation | W8: Reverse non-cash D&A expense
A9: Non-current financial assets | B9: 1000000 | C9: 1533000 | D9: Balance sheet, PDF p. 16 | K9: PPE net carrying amount derecognized | L9: 98000 | M9: Note 17, PDF pp. 69-70 | N9: Gross derecognitions of 835 less accumulated depreciation derecognized of 737. | P9: Less: dividend payable accrued in trade payables | R9: Reclass non-operating payable out of supplier payments | S9: January 2026 shareholder remuneration was accrued in 2025 trade payables, not paid in 2025. | U9: Adjust: impairment charge/(reversal) | W9: Reverse P&L impairment charge/reversal line
A10: Deferred tax assets | B10: 3368000 | C10: 4405000 | D10: Balance sheet, PDF p. 16 | K10: Intangible net carrying amount derecognized | L10: 41000 | M10: Note 16, PDF p. 67 | N10: Gross derecognitions of 177 less accumulated amortization derecognized of 136. | P10: Cash paid to employees | R10: Personnel expense used as cash proxy | S10: Payroll accrual balances are not separately disclosed. | U10: Adjust: equity method income | W10: Remove equity-accounted income before dividends/cash movements
A11: Other non-current assets | B11: 1394000 | C11: 1696000 | D11: Balance sheet, PDF p. 16 | K11: Gain on disposal and derecognition | L11: 14000 | M11: Income statement, PDF p. 14 | N11: Used to estimate disposal proceeds where cash proceeds are not disclosed. | P11: Interest received | R11: Interest income | U11: Adjust: fair value of financial instruments | W11: Reverse mark-to-market P&L movement
A12: NON-CURRENT ASSETS | B12: 38055000 | C12: 41922000 | D12: Balance sheet, PDF p. 16 | K12: Disposal proceeds proxy | L12: =L9+L10+L11 -> 153000 | M12: Formula: net carrying amount derecognized + gain/loss | N12: Proxy, not a plug. | P12: Interest paid | R12: Interest expense | U12: Adjust: exchange gains/(losses) | W12: Reverse P&L FX gain/loss where cash effect is not separately observable
A13: Non-current assets held for sale | B13: 1227000 | C13: 524000 | D13: Balance sheet, PDF p. 16 | K13: Equity-method net investments | L13: 20000 | M13: Note 18, PDF p. 72 | N13: Reported roll-forward line. Treated as investing outflow. | P13: Income taxes paid/accrued | R13: Income tax expense used as cash proxy | S13: Current tax payable/receivable movements are not separately disclosed. | U13: Adjust: gains/(losses) on disposal and derecognition | W13: Remove disposal result from operating cash flow
A14: Inventories | B14: 5475000 | C14: 6211000 | D14: Balance sheet, PDF p. 16 | K14: Dividends from equity-accounted investments | L14: 93000 | M14: Note 18, PDF p. 72 | N14: Reported roll-forward line. Treated as investing inflow. | P14: Cash settlements of provisions | R14: Cancellation due to payment from provisions note | U14: Adjust: impairment of financial instruments | W14: Reverse expected-credit-loss/provision line
A15: Trade and other receivables | B15: 6557000 | C15: 7364000 | D15: Balance sheet, PDF p. 16 | K15: Net equity-method investing cash flow | L15: =L14-L13 -> 73000 | M15: Formula: dividends - net investments | N15: Observable from equity-method roll-forward. | P15: Operating cash flow - direct observable subtotal | U15: Decrease/(increase) in inventories | W15: Prior balance - current balance
A16: Other current assets | B16: 135000 | C16: 296000 | D16: Balance sheet, PDF p. 16 | K16: Dividend payable accrued, not paid | L16: 552000 | M16: Note 11.3, PDF p. 50 | N16: January 2026 remuneration recognized in 2025 trade and other payables; excluded from 2025 operating cash flow. | P16: Cash flow from investing activities | U16: Decrease/(increase) in trade and other receivables | W16: Prior balance - current balance
A17: Other current financial assets | B17: 4718000 | C17: 2111000 | D17: Balance sheet, PDF p. 16 | K17: Provision cash payments | L17: 343000 | M17: Note 20.1, PDF p. 76 | N17: Cancellation due to payment. | P17: Cash capex proxy - PPE and intangible assets | R17: Gross PPE/intangible investments less non-cash lease additions | S17: Uses notes 16 and 17 instead of net balance movement, avoiding FX/scope distortions. | U17: Decrease/(increase) in other current assets | W17: Prior balance - current balance
A18: Cash and cash equivalents | B18: 3261000 | C18: 4758000 | D18: Balance sheet, PDF p. 16 | K18: Provision charges net of credits | L18: 1254000 | M18: Note 20.1, PDF p. 76 | N18: Provisions charged to income of 1,313 less credited to income of 59. | P18: Disposal proceeds proxy - PPE and intangible assets | R18: Net carrying amount derecognized plus P&L disposal gain | U18: Increase/(decrease) in trade and other payables | W18: Current balance - prior balance
A19: CURRENT ASSETS | B19: 21373000 | C19: 21264000 | D19: Balance sheet, PDF p. 16 | K19: Held-for-sale disposal proceeds proxy | L19: 302000 | M19: Note 19, PDF p. 75; Note 15.1 FX average, PDF p. 61 | N19: USD 341m remaining/completed proceeds translated at 2025 average EUR/USD of 1.13; rounded to EUR thousands. | P19: Net equity-method investing cash flow | R19: Dividends from equity-accounted investments less net investments | U19: Less: dividend payable accrued in trade payables | W19: Reclass non-operating payable out of operating working capital
A20: TOTAL ASSETS | B20: 59428000 | C20: 63186000 | D20: Balance sheet, PDF p. 16 | K20: Indonesia Corridor disposal proceeds proxy | L20: 376000 | M20: Note 17, PDF p. 69; Note 15.1 FX average, PDF p. 61 | N20: USD 425m sale price translated at 2025 average EUR/USD of 1.13; Sakakemang excluded because approval was pending and amount was immaterial/held for sale. | P20: Net movement in financial assets | R20: Change in Note 13 financial assets excluding cash | U20: Increase/(decrease) in provisions | W20: Current plus non-current provisions movement | X20: Kept as a balance-sheet movement because related scope/FX offsets are not fully allocable without the published cash flow statement.
A21: EQUITY AND LIABILITIES | K21: Net financial assets movement excluding cash | L21: -2084000 | M21: Note 13, PDF p. 56 | N21: Derived from financial assets excluding cash: 2025 EUR 5,942m less 2024 EUR 3,858m. Includes financial asset lines not captured by the two balance-sheet headings alone. | P21: Held-for-sale disposal proceeds proxy | R21: Completed asset disposals disclosed in Note 19, translated using disclosed average FX | U21: Deferred tax balance movement | W21: Change in net deferred tax liability/(asset) | X21: Included as an observable balance-sheet movement; OCI/FX/current tax split is not available.
A22: Share capital | B22: 1105000 | C22: 1157000 | D22: Statement of changes in equity, PDF p. 17 | K22: Public grants received for hydrogen projects | L22: 315000 | M22: Note 19, PDF p. 75 | N22: Funds received from public authorities, classified as financing/other inflow in reconstruction. | P22: Indonesia Corridor disposal proceeds proxy | R22: Completed asset disposal disclosed in Note 17, translated using disclosed average FX | U22: Operating cash flow - indirect observable subtotal
A23: Retained earnings, reserves, share premium and dividends | B23: 20607000 | C23: 20681000 | D23: Statement of changes in equity, PDF p. 17. Repsol groups these items in one column. | K23: Subordinated hybrid bond issues | L23: 1500000 | M23: Note 11.4, PDF p. 50 | N23: Two EUR 750m perpetual subordinated bond issues. | P23: Investing cash flow - observable subtotal | U23: Cash flow from investing activities
A24: Treasury shares and own equity investments | B24: -3000 | C24: -2000 | D24: Statement of changes in equity, PDF p. 17 | K24: Subordinated hybrid repurchases/redemptions | L24: -758000 | M24: Note 11.4, PDF p. 51 | N24: EUR 614m repurchase plus EUR 144m redemption. | P24: Cash flow from financing activities | U24: Investing cash flow - observable subtotal | W24: Same observable investing reconstruction as direct method
A25: Other equity instruments | B25: 3046000 | C25: 2291000 | D25: Statement of changes in equity, PDF p. 17 | K25: Net subordinated hybrid cash flow | L25: =L23+L24 -> 742000 | M25: Formula: issues + repurchases/redemptions | N25: Cash financing effect before coupons classified in equity. | P25: Net change in financial liabilities | R25: Change in current and non-current financial liabilities | U25: Cash flow from financing activities
A26: Net income attributable to the parent | B26: 1899000 | C26: 1756000 | D26: Statement of changes in equity, PDF p. 17 | K26: Treasury share market purchases | L26: -727000 | M26: Note 11.2, PDF p. 49 | N26: Market purchases. | P26: Dividends and shareholder remuneration | R26: Equity movement memo | U26: Financing cash flow - observable subtotal | W26: Same observable financing reconstruction as direct method
A27: Other cumulative comprehensive income | B27: -1514000 | C27: 606000 | D27: Balance sheet and statement of changes in equity, PDF pp. 16-17 | K27: Treasury share market sales | L27: 25000 | M27: Note 11.2, PDF p. 49 | N27: Market sales. | P27: Treasury share cash flow | R27: Market purchases, market sales and derivative settlements disclosed in notes | U27: Subtotal - independently sourced items (I + II + III) | X27: Subtotal before the explicit balance-sheet reconciliation line.
A28: Non-controlling interests | B28: 2478000 | C28: 2610000 | D28: Balance sheet and statement of changes in equity, PDF pp. 16-17 | K28: Treasury share derivatives settlement | L28: -103000 | M28: Note 14, PDF p. 61 | N28: EUR 32m partial collar cancellation plus EUR 71m equity swap physical settlement. | P28: Subordinated perpetual debentures cash flow | R28: Hybrid issues less repurchases/redemptions disclosed in notes | U28: Reconciliation to actual cash movement
A29: EQUITY | B29: 27618000 | C29: 29099000 | D29: Balance sheet, PDF p. 16; detailed using PDF p. 17 | K29: Net treasury share cash flow | L29: =L26+L27+L28 -> -805000 | M29: Formula: purchases + sales + derivative settlements | N29: Cash financing effect, excluding non-cash capital reductions. | P29: Other partner/scope/equity movements | R29: Equity movement memo items other than dividends, treasury shares and perpetual debentures | U29: Actual net increase/(decrease) in cash and cash equivalents (per Balance Sheet) | W29: Current-year cash less prior-year cash from the balance sheet
A30: Non-current provisions | B30: 3002000 | C30: 5137000 | D30: Balance sheet, PDF p. 16 | P30: Public grants received for hydrogen projects | R30: Funds received from public authorities disclosed in Note 19 | U30: Unreconciled / non-cash and other unallocated items | W30: Actual balance-sheet cash movement less independently sourced subtotal | X30: Visible reconciliation line, not an operating/investing/financing plug.
A31: Non-current financial liabilities | B31: 11410000 | C31: 9433000 | D31: Balance sheet, PDF p. 16 | P31: Liabilities associated with held-for-sale assets | R31: Change in related liability line | U31: Net increase/(decrease) in cash and cash equivalents (= actual, by construction) | W31: Subtotal plus visible reconciliation line
A32: Deferred tax liabilities and other tax items | B32: 2419000 | C32: 2658000 | D32: Balance sheet, PDF p. 16 | P32: Financing cash flow - observable subtotal | U32: Cash and cash equivalents at beginning of period
A33: Other non-current liabilities | B33: 1099000 | C33: 1176000 | D33: Balance sheet, PDF p. 16 | P33: Subtotal - independently sourced items (I + II + III) | S33: Subtotal before the explicit balance-sheet reconciliation line. | U33: Cash and cash equivalents at end of period | W33: Reconciles to balance sheet cash by construction
A34: NON-CURRENT LIABILITIES | B34: 17930000 | C34: 18404000 | D34: Balance sheet, PDF p. 16 | P34: Reconciliation to actual cash movement | U34: Check: ending cash per statement above vs. balance sheet | X34: Must be zero after the explicit reconciliation line.
A35: Liabilities associated with non-current assets held for sale | B35: 466000 | C35: 4000 | D35: Balance sheet, PDF p. 16 | P35: Actual net increase/(decrease) in cash and cash equivalents (per Balance Sheet) | R35: Current-year cash less prior-year cash from the balance sheet
A36: Current provisions | B36: 1177000 | C36: 1514000 | D36: Balance sheet, PDF p. 16 | P36: Unreconciled / non-cash and other unallocated items | R36: Actual balance-sheet cash movement less independently sourced subtotal | S36: Visible reconciliation line, not an operating/investing/financing plug.
A37: Current financial liabilities | B37: 2018000 | C37: 2945000 | D37: Balance sheet, PDF p. 16 | P37: Net increase/(decrease) in cash and cash equivalents (= actual, by construction) | R37: Subtotal plus visible reconciliation line
A38: Trade and other payables | B38: 10219000 | C38: 11220000 | D38: Balance sheet, PDF p. 16 | P38: Cash and cash equivalents at beginning of period
A39: CURRENT LIABILITIES | B39: 13880000 | C39: 15683000 | D39: Balance sheet, PDF p. 16 | P39: Cash and cash equivalents at end of period | R39: Reconciles to balance sheet cash by construction
A40: TOTAL EQUITY AND LIABILITIES | B40: 59428000 | C40: 63186000 | D40: Balance sheet, PDF p. 16 | P40: Check: ending cash per statement above vs. balance sheet | S40: Must be zero after the explicit reconciliation line.
A42: EQUITY MOVEMENT MEMO | D42: Statement of changes in equity, PDF p. 17
...

Sheet Indirect CF
A1: ='Balance Sheet'!U$1 -> Repsol Cash Flow Statement - Indirect Method
A2: ='Balance Sheet'!U$2 -> Reconstructed from P&L, balance sheet, equity roll-forward and selected source notes; the published cash flow statement was not used.
A4: ='Balance Sheet'!U$4 -> Line item | B4: ='Balance Sheet'!V$4 -> 2025 | C4: ='Balance Sheet'!W$4 -> Formula / source logic | D4: ='Balance Sheet'!X$4 -> Technical note
A5: =IF('Balance Sheet'!U$5="","",'Balance Sheet'!U$5) -> Beginning cash and cash equivalents | B5: =SUMIF('Balance Sheet'!$A$1:$A$90,"Cash and cash equivalents",'Balance Sheet'!$C$1:$C$90) -> 4758000 | C5: =IF('Balance Sheet'!W$5="","",'Balance Sheet'!W$5) -> Prior-year balance sheet cash | D5: =IF('Balance Sheet'!X$5="","",'Balance Sheet'!X$5)
A6: =IF('Balance Sheet'!U$6="","",'Balance Sheet'!U$6) -> Cash flow from operating activities - indirect method | B6: =IF('Balance Sheet'!V$6="","",'Balance Sheet'!V$6) | C6: =IF('Balance Sheet'!W$6="","",'Balance Sheet'!W$6) | D6: =IF('Balance Sheet'!X$6="","",'Balance Sheet'!X$6)
A7: =IF('Balance Sheet'!U$7="","",'Balance Sheet'!U$7) -> Consolidated net income | B7: =SUMIF('P&L'!$A$1:$A$80,"CONSOLIDATED NET INCOME / (LOSS) FOR THE PERIOD",'P&L'!$B$1:$B$80) -> 2100000 | C7: =IF('Balance Sheet'!W$7="","",'Balance Sheet'!W$7) -> Starts from net income, per user request | D7: =IF('Balance Sheet'!X$7="","",'Balance Sheet'!X$7)
A8: =IF('Balance Sheet'!U$8="","",'Balance Sheet'!U$8) -> Add back: amortization and depreciation | B8: =-SUMIF('P&L'!$A$1:$A$80,"Amortization and depreciation of non-current assets",'P&L'!$B$1:$B$80) -> 2439000 | C8: =IF('Balance Sheet'!W$8="","",'Balance Sheet'!W$8) -> Reverse non-cash D&A expense | D8: =IF('Balance Sheet'!X$8="","",'Balance Sheet'!X$8)
A9: =IF('Balance Sheet'!U$9="","",'Balance Sheet'!U$9) -> Adjust: impairment charge/(reversal) | B9: =-SUMIF('P&L'!$A$1:$A$80,"(Charges for)/Reversal of impairment",'P&L'!$B$1:$B$80) -> -1000 | C9: =IF('Balance Sheet'!W$9="","",'Balance Sheet'!W$9) -> Reverse P&L impairment charge/reversal line | D9: =IF('Balance Sheet'!X$9="","",'Balance Sheet'!X$9)
A10: =IF('Balance Sheet'!U$10="","",'Balance Sheet'!U$10) -> Adjust: equity method income | B10: =-SUMIF('P&L'!$A$1:$A$80,"Net income from investments accounted for using the equity method",'P&L'!$B$1:$B$80) -> -53000 | C10: =IF('Balance Sheet'!W$10="","",'Balance Sheet'!W$10) -> Remove equity-accounted income before dividends/cash movements | D10: =IF('Balance Sheet'!X$10="","",'Balance Sheet'!X$10)
A11: =IF('Balance Sheet'!U$11="","",'Balance Sheet'!U$11) -> Adjust: fair value of financial instruments | B11: =-SUMIF('P&L'!$A$1:$A$80,"Change in fair value of financial instruments",'P&L'!$B$1:$B$80) -> 298000 | C11: =IF('Balance Sheet'!W$11="","",'Balance Sheet'!W$11) -> Reverse mark-to-market P&L movement | D11: =IF('Balance Sheet'!X$11="","",'Balance Sheet'!X$11)
A12: =IF('Balance Sheet'!U$12="","",'Balance Sheet'!U$12) -> Adjust: exchange gains/(losses) | B12: =-SUMIF('P&L'!$A$1:$A$80,"Exchange gains/(losses)",'P&L'!$B$1:$B$80) -> -468000 | C12: =IF('Balance Sheet'!W$12="","",'Balance Sheet'!W$12) -> Reverse P&L FX gain/loss where cash effect is not separately observable | D12: =IF('Balance Sheet'!X$12="","",'Balance Sheet'!X$12)
A13: =IF('Balance Sheet'!U$13="","",'Balance Sheet'!U$13) -> Adjust: gains/(losses) on disposal and derecognition | B13: =-SUMIF('P&L'!$A$1:$A$80,"Gains/(Losses) on disposal and derecognition of assets",'P&L'!$B$1:$B$80) -> -14000 | C13: =IF('Balance Sheet'!W$13="","",'Balance Sheet'!W$13) -> Remove disposal result from operating cash flow | D13: =IF('Balance Sheet'!X$13="","",'Balance Sheet'!X$13)
A14: =IF('Balance Sheet'!U$14="","",'Balance Sheet'!U$14) -> Adjust: impairment of financial instruments | B14: =-SUMIF('P&L'!$A$1:$A$80,"(Provision for)/Reversal of impairment of financial instruments",'P&L'!$B$1:$B$80) -> -25000 | C14: =IF('Balance Sheet'!W$14="","",'Balance Sheet'!W$14) -> Reverse expected-credit-loss/provision line | D14: =IF('Balance Sheet'!X$14="","",'Balance Sheet'!X$14)
A15: =IF('Balance Sheet'!U$15="","",'Balance Sheet'!U$15) -> Decrease/(increase) in inventories | B15: =SUMIF('Balance Sheet'!$A$1:$A$90,"Inventories",'Balance Sheet'!$C$1:$C$90)-SUMIF('Balance Sheet'!$A$1:$A$90,"Inventories",'Balance Sheet'!$B$1:$B$90) -> 736000 | C15: =IF('Balance Sheet'!W$15="","",'Balance Sheet'!W$15) -> Prior balance - current balance | D15: =IF('Balance Sheet'!X$15="","",'Balance Sheet'!X$15)
A16: =IF('Balance Sheet'!U$16="","",'Balance Sheet'!U$16) -> Decrease/(increase) in trade and other receivables | B16: =SUMIF('Balance Sheet'!$A$1:$A$90,"Trade and other receivables",'Balance Sheet'!$C$1:$C$90)-SUMIF('Balance Sheet'!$A$1:$A$90,"Trade and other receivables",'Balance Sheet'!$B$1:$B$90) -> 807000 | C16: =IF('Balance Sheet'!W$16="","",'Balance Sheet'!W$16) -> Prior balance - current balance | D16: =IF('Balance Sheet'!X$16="","",'Balance Sheet'!X$16)
A17: =IF('Balance Sheet'!U$17="","",'Balance Sheet'!U$17) -> Decrease/(increase) in other current assets | B17: =SUMIF('Balance Sheet'!$A$1:$A$90,"Other current assets",'Balance Sheet'!$C$1:$C$90)-SUMIF('Balance Sheet'!$A$1:$A$90,"Other current assets",'Balance Sheet'!$B$1:$B$90) -> 161000 | C17: =IF('Balance Sheet'!W$17="","",'Balance Sheet'!W$17) -> Prior balance - current balance | D17: =IF('Balance Sheet'!X$17="","",'Balance Sheet'!X$17)
A18: =IF('Balance Sheet'!U$18="","",'Balance Sheet'!U$18) -> Increase/(decrease) in trade and other payables | B18: =SUMIF('Balance Sheet'!$A$1:$A$90,"Trade and other payables",'Balance Sheet'!$B$1:$B$90)-SUMIF('Balance Sheet'!$A$1:$A$90,"Trade and other payables",'Balance Sheet'!$C$1:$C$90) -> -1001000 | C18: =IF('Balance Sheet'!W$18="","",'Balance Sheet'!W$18) -> Current balance - prior balance | D18: =IF('Balance Sheet'!X$18="","",'Balance Sheet'!X$18)
A19: =IF('Balance Sheet'!U$19="","",'Balance Sheet'!U$19) -> Less: dividend payable accrued in trade payables | B19: =-SUMIF('Balance Sheet'!$K$1:$K$120,"Dividend payable accrued, not paid",'Balance Sheet'!$L$1:$L$120) -> -552000 | C19: =IF('Balance Sheet'!W$19="","",'Balance Sheet'!W$19) -> Reclass non-operating payable out of operating working capital | D19: =IF('Balance Sheet'!X$19="","",'Balance Sheet'!X$19)
A20: =IF('Balance Sheet'!U$20="","",'Balance Sheet'!U$20) -> Increase/(decrease) in provisions | B20: =(SUMIF('Balance Sheet'!$A$1:$A$90,"Current provisions",'Balance Sheet'!$B$1:$B$90)+SUMIF('Balance Sheet'!$A$1:$A$90,"Non-current provisions",'Balance Sheet'!$B$1:$B$90))-(SUMIF('Balance Sheet'!$A$1:$A$90,"Current provisions",'Balance Sheet'!$C$1:$C$90)+SUMIF('Balance Sheet'!$A$1:$A$90,"Non-current provisions",'Balance Sheet'!$C$1:$C$90)) -> -2472000 | C20: =IF('Balance Sheet'!W$20="","",'Balance Sheet'!W$20) -> Current plus non-current provisions movement | D20: =IF('Balance Sheet'!X$20="","",'Balance Sheet'!X$20) -> Kept as a balance-sheet movement because related scope/FX offsets are not fully allocable without the published cash flow statement.
A21: =IF('Balance Sheet'!U$21="","",'Balance Sheet'!U$21) -> Deferred tax balance movement | B21: =(SUMIF('Balance Sheet'!$A$1:$A$90,"Deferred tax liabilities and other tax items",'Balance Sheet'!$B$1:$B$90)-SUMIF('Balance Sheet'!$A$1:$A$90,"Deferred tax assets",'Balance Sheet'!$B$1:$B$90))-(SUMIF('Balance Sheet'!$A$1:$A$90,"Deferred tax liabilities and other tax items",'Balance Sheet'!$C$1:$C$90)-SUMIF('Balance Sheet'!$A$1:$A$90,"Deferred tax assets",'Balance Sheet'!$C$1:$C$90)) -> 798000 | C21: =IF('Balance Sheet'!W$21="","",'Balance Sheet'!W$21) -> Change in net deferred tax liability/(asset) | D21: =IF('Balance Sheet'!X$21="","",'Balance Sheet'!X$21) -> Included as an observable balance-sheet movement; OCI/FX/current tax split is not available.
A22: =IF('Balance Sheet'!U$22="","",'Balance Sheet'!U$22) -> Operating cash flow - indirect observable subtotal | B22: =SUM(B7:B21) -> 2753000 | C22: =IF('Balance Sheet'!W$22="","",'Balance Sheet'!W$22) | D22: =IF('Balance Sheet'!X$22="","",'Balance Sheet'!X$22)
A23: =IF('Balance Sheet'!U$23="","",'Balance Sheet'!U$23) -> Cash flow from investing activities | B23: =IF('Balance Sheet'!V$23="","",'Balance Sheet'!V$23) | C23: =IF('Balance Sheet'!W$23="","",'Balance Sheet'!W$23) | D23: =IF('Balance Sheet'!X$23="","",'Balance Sheet'!X$23)
A24: =IF('Balance Sheet'!U$24="","",'Balance Sheet'!U$24) -> Investing cash flow - observable subtotal | B24: ='Direct CF'!B23 -> -4791000 | C24: =IF('Balance Sheet'!W$24="","",'Balance Sheet'!W$24) -> Same observable investing reconstruction as direct method | D24: =IF('Balance Sheet'!X$24="","",'Balance Sheet'!X$24)
A25: =IF('Balance Sheet'!U$25="","",'Balance Sheet'!U$25) -> Cash flow from financing activities | B25: =IF('Balance Sheet'!V$25="","",'Balance Sheet'!V$25) | C25: =IF('Balance Sheet'!W$25="","",'Balance Sheet'!W$25) | D25: =IF('Balance Sheet'!X$25="","",'Balance Sheet'!X$25)
A26: =IF('Balance Sheet'!U$26="","",'Balance Sheet'!U$26) -> Financing cash flow - observable subtotal | B26: ='Direct CF'!B32 -> 547000 | C26: =IF('Balance Sheet'!W$26="","",'Balance Sheet'!W$26) -> Same observable financing reconstruction as direct method | D26: =IF('Balance Sheet'!X$26="","",'Balance Sheet'!X$26)
A27: =IF('Balance Sheet'!U$27="","",'Balance Sheet'!U$27) -> Subtotal - independently sourced items (I + II + III) | B27: =B22+B24+B26 -> -1491000 | C27: =IF('Balance Sheet'!W$27="","",'Balance Sheet'!W$27) | D27: =IF('Balance Sheet'!X$27="","",'Balance Sheet'!X$27) -> Subtotal before the explicit balance-sheet reconciliation line.
A28: =IF('Balance Sheet'!U$28="","",'Balance Sheet'!U$28) -> Reconciliation to actual cash movement | B28: =IF('Balance Sheet'!V$28="","",'Balance Sheet'!V$28) | C28: =IF('Balance Sheet'!W$28="","",'Balance Sheet'!W$28) | D28: =IF('Balance Sheet'!X$28="","",'Balance Sheet'!X$28)
A29: =IF('Balance Sheet'!U$29="","",'Balance Sheet'!U$29) -> Actual net increase/(decrease) in cash and cash equivalents (per Balance Sheet) | B29: =SUMIF('Balance Sheet'!$A$1:$A$90,"Cash and cash equivalents",'Balance Sheet'!$B$1:$B$90)-SUMIF('Balance Sheet'!$A$1:$A$90,"Cash and cash equivalents",'Balance Sheet'!$C$1:$C$90) -> -1497000 | C29: =IF('Balance Sheet'!W$29="","",'Balance Sheet'!W$29) -> Current-year cash less prior-year cash from the balance sheet | D29: =IF('Balance Sheet'!X$29="","",'Balance Sheet'!X$29)
A30: =IF('Balance Sheet'!U$30="","",'Balance Sheet'!U$30) -> Unreconciled / non-cash and other unallocated items | B30: =B29-B27 -> -6000 | C30: =IF('Balance Sheet'!W$30="","",'Balance Sheet'!W$30) -> Actual balance-sheet cash movement less independently sourced subtotal | D30: =IF('Balance Sheet'!X$30="","",'Balance Sheet'!X$30) -> Visible reconciliation line, not an operating/investing/financing plug.
A31: =IF('Balance Sheet'!U$31="","",'Balance Sheet'!U$31) -> Net increase/(decrease) in cash and cash equivalents (= actual, by construction) | B31: =B27+B30 -> -1497000 | C31: =IF('Balance Sheet'!W$31="","",'Balance Sheet'!W$31) -> Subtotal plus visible reconciliation line | D31: =IF('Balance Sheet'!X$31="","",'Balance Sheet'!X$31)
A32: =IF('Balance Sheet'!U$32="","",'Balance Sheet'!U$32) -> Cash and cash equivalents at beginning of period | B32: =B5 -> 4758000 | C32: =IF('Balance Sheet'!W$32="","",'Balance Sheet'!W$32) | D32: =IF('Balance Sheet'!X$32="","",'Balance Sheet'!X$32)
A33: =IF('Balance Sheet'!U$33="","",'Balance Sheet'!U$33) -> Cash and cash equivalents at end of period | B33: =B32+B31 -> 3261000 | C33: =IF('Balance Sheet'!W$33="","",'Balance Sheet'!W$33) -> Reconciles to balance sheet cash by construction | D33: =IF('Balance Sheet'!X$33="","",'Balance Sheet'!X$33)
A34: =IF('Balance Sheet'!U$34="","",'Balance Sheet'!U$34) -> Check: ending cash per statement above vs. balance sheet | B34: =B33-SUMIF('Balance Sheet'!$A$1:$A$90,"Cash and cash equivalents",'Balance Sheet'!$B$1:$B$90) -> 0 | C34: =IF('Balance Sheet'!W$34="","",'Balance Sheet'!W$34) | D34: =IF('Balance Sheet'!X$34="","",'Balance Sheet'!X$34) -> Must be zero after the explicit reconciliation line.

Sheet Direct CF
A1: ='Balance Sheet'!P$1 -> Repsol Cash Flow Statement - Direct Method
A2: ='Balance Sheet'!P$2 -> Reconstructed from P&L, balance sheet, equity roll-forward and selected source notes; the published cash flow statement was not used.
A4: ='Balance Sheet'!P$4 -> Line item | B4: ='Balance Sheet'!Q$4 -> 2025 | C4: ='Balance Sheet'!R$4 -> Formula / source logic | D4: ='Balance Sheet'!S$4 -> Technical note
A5: =IF('Balance Sheet'!P$5="","",'Balance Sheet'!P$5) -> Beginning cash and cash equivalents | B5: =SUMIF('Balance Sheet'!$A$1:$A$90,"Cash and cash equivalents",'Balance Sheet'!$C$1:$C$90) -> 4758000 | C5: =IF('Balance Sheet'!R$5="","",'Balance Sheet'!R$5) -> Prior-year balance sheet cash | D5: =IF('Balance Sheet'!S$5="","",'Balance Sheet'!S$5)
A6: =IF('Balance Sheet'!P$6="","",'Balance Sheet'!P$6) -> Cash flow from operating activities - direct method | B6: =IF('Balance Sheet'!Q$6="","",'Balance Sheet'!Q$6) | C6: =IF('Balance Sheet'!R$6="","",'Balance Sheet'!R$6) | D6: =IF('Balance Sheet'!S$6="","",'Balance Sheet'!S$6)
A7: =IF('Balance Sheet'!P$7="","",'Balance Sheet'!P$7) -> Cash receipts from customers | B7: =SUMIF('P&L'!$A$1:$A$80,"Sales",'P&L'!$B$1:$B$80)+SUMIF('P&L'!$A$1:$A$80,"Income from services rendered and other income",'P&L'!$B$1:$B$80)+(SUMIF('Balance Sheet'!$A$1:$A$90,"Trade and other receivables",'Balance Sheet'!$C$1:$C$90)-SUMIF('Balance Sheet'!$A$1:$A$90,"Trade and other receivables",'Balance Sheet'!$B$1:$B$90)) -> 55668000 | C7: =IF('Balance Sheet'!R$7="","",'Balance Sheet'!R$7) -> Sales + services/other income - increase in trade receivables | D7: =IF('Balance Sheet'!S$7="","",'Balance Sheet'!S$7) -> Uses trade and other receivables because customer receivables are not separately disclosed in the balance sheet.
A8: =IF('Balance Sheet'!P$8="","",'Balance Sheet'!P$8) -> Cash paid to suppliers and other operating costs | B8: =SUMIF('P&L'!$A$1:$A$80,"Procurements",'P&L'!$B$1:$B$80)+SUMIF('P&L'!$A$1:$A$80,"Transport and freights",'P&L'!$B$1:$B$80)+SUMIF('P&L'!$A$1:$A$80,"Supplies",'P&L'!$B$1:$B$80)+SUMIF('P&L'!$A$1:$A$80,"Other operating income/(expenses)",'P&L'!$B$1:$B$80)-(SUMIF('Balance Sheet'!$A$1:$A$90,"Inventories",'Balance Sheet'!$B$1:$B$90)-SUMIF('Balance Sheet'!$A$1:$A$90,"Inventories",'Balance Sheet'!$C$1:$C$90))+(SUMIF('Balance Sheet'!$A$1:$A$90,"Trade and other payables",'Balance Sheet'!$B$1:$B$90)-SUMIF('Balance Sheet'!$A$1:$A$90,"Trade and other payables",'Balance Sheet'!$C$1:$C$90)) -> -47884000 | C8: =IF('Balance Sheet'!R$8="","",'Balance Sheet'!R$8) -> Procurements + transport + supplies + other opex - inventory increase + payables increase | D8: =IF('Balance Sheet'!S$8="","",'Balance Sheet'!S$8) -> Trade payables are not separately disclosed; this uses the reported trade and other payables line.
A9: =IF('Balance Sheet'!P$9="","",'Balance Sheet'!P$9) -> Less: dividend payable accrued in trade payables | B9: =-SUMIF('Balance Sheet'!$K$1:$K$120,"Dividend payable accrued, not paid",'Balance Sheet'!$L$1:$L$120) -> -552000 | C9: =IF('Balance Sheet'!R$9="","",'Balance Sheet'!R$9) -> Reclass non-operating payable out of supplier payments | D9: =IF('Balance Sheet'!S$9="","",'Balance Sheet'!S$9) -> January 2026 shareholder remuneration was accrued in 2025 trade payables, not paid in 2025.
A10: =IF('Balance Sheet'!P$10="","",'Balance Sheet'!P$10) -> Cash paid to employees | B10: =SUMIF('P&L'!$A$1:$A$80,"Personnel expenses",'P&L'!$B$1:$B$80) -> -2178000 | C10: =IF('Balance Sheet'!R$10="","",'Balance Sheet'!R$10) -> Personnel expense used as cash proxy | D10: =IF('Balance Sheet'!S$10="","",'Balance Sheet'!S$10) -> Payroll accrual balances are not separately disclosed.
A11: =IF('Balance Sheet'!P$11="","",'Balance Sheet'!P$11) -> Interest received | B11: =SUMIF('P&L'!$A$1:$A$80,"Interest income",'P&L'!$B$1:$B$80) -> 257000 | C11: =IF('Balance Sheet'!R$11="","",'Balance Sheet'!R$11) -> Interest income | D11: =IF('Balance Sheet'!S$11="","",'Balance Sheet'!S$11)
A12: =IF('Balance Sheet'!P$12="","",'Balance Sheet'!P$12) -> Interest paid | B12: =SUMIF('P&L'!$A$1:$A$80,"Interest expenses",'P&L'!$B$1:$B$80) -> -291000 | C12: =IF('Balance Sheet'!R$12="","",'Balance Sheet'!R$12) -> Interest expense | D12: =IF('Balance Sheet'!S$12="","",'Balance Sheet'!S$12)
A13: =IF('Balance Sheet'!P$13="","",'Balance Sheet'!P$13) -> Income taxes paid/accrued | B13: =SUMIF('P&L'!$A$1:$A$80,"Income tax",'P&L'!$B$1:$B$80) -> -717000 | C13: =IF('Balance Sheet'!R$13="","",'Balance Sheet'!R$13) -> Income tax expense used as cash proxy | D13: =IF('Balance Sheet'!S$13="","",'Balance Sheet'!S$13) -> Current tax payable/receivable movements are not separately disclosed.
A14: =IF('Balance Sheet'!P$14="","",'Balance Sheet'!P$14) -> Cash settlements of provisions | B14: =-SUMIF('Balance Sheet'!$K$1:$K$120,"Provision cash payments",'Balance Sheet'!$L$1:$L$120) -> -343000 | C14: =IF('Balance Sheet'!R$14="","",'Balance Sheet'!R$14) -> Cancellation due to payment from provisions note | D14: =IF('Balance Sheet'!S$14="","",'Balance Sheet'!S$14)
A15: =IF('Balance Sheet'!P$15="","",'Balance Sheet'!P$15) -> Operating cash flow - direct observable subtotal | B15: =SUM(B7:B14) -> 3960000 | C15: =IF('Balance Sheet'!R$15="","",'Balance Sheet'!R$15) | D15: =IF('Balance Sheet'!S$15="","",'Balance Sheet'!S$15)
A16: =IF('Balance Sheet'!P$16="","",'Balance Sheet'!P$16) -> Cash flow from investing activities | B16: =IF('Balance Sheet'!Q$16="","",'Balance Sheet'!Q$16) | C16: =IF('Balance Sheet'!R$16="","",'Balance Sheet'!R$16) | D16: =IF('Balance Sheet'!S$16="","",'Balance Sheet'!S$16)
A17: =IF('Balance Sheet'!P$17="","",'Balance Sheet'!P$17) -> Cash capex proxy - PPE and intangible assets | B17: =-SUMIF('Balance Sheet'!$K$1:$K$120,"Cash capex proxy",'Balance Sheet'!$L$1:$L$120) -> -3611000 | C17: =IF('Balance Sheet'!R$17="","",'Balance Sheet'!R$17) -> Gross PPE/intangible investments less non-cash lease additions | D17: =IF('Balance Sheet'!S$17="","",'Balance Sheet'!S$17) -> Uses notes 16 and 17 instead of net balance movement, avoiding FX/scope distortions.
A18: =IF('Balance Sheet'!P$18="","",'Balance Sheet'!P$18) -> Disposal proceeds proxy - PPE and intangible assets | B18: =SUMIF('Balance Sheet'!$K$1:$K$120,"Disposal proceeds proxy",'Balance Sheet'!$L$1:$L$120) -> 153000 | C18: =IF('Balance Sheet'!R$18="","",'Balance Sheet'!R$18) -> Net carrying amount derecognized plus P&L disposal gain | D18: =IF('Balance Sheet'!S$18="","",'Balance Sheet'!S$18)
A19: =IF('Balance Sheet'!P$19="","",'Balance Sheet'!P$19) -> Net equity-method investing cash flow | B19: =SUMIF('Balance Sheet'!$K$1:$K$120,"Net equity-method investing cash flow",'Balance Sheet'!$L$1:$L$120) -> 73000 | C19: =IF('Balance Sheet'!R$19="","",'Balance Sheet'!R$19) -> Dividends from equity-accounted investments less net investments | D19: =IF('Balance Sheet'!S$19="","",'Balance Sheet'!S$19)
A20: =IF('Balance Sheet'!P$20="","",'Balance Sheet'!P$20) -> Net movement in financial assets | B20: =SUMIF('Balance Sheet'!$K$1:$K$120,"Net financial assets movement excluding cash",'Balance Sheet'!$L$1:$L$120) -> -2084000 | C20: =IF('Balance Sheet'!R$20="","",'Balance Sheet'!R$20) -> Change in Note 13 financial assets excluding cash | D20: =IF('Balance Sheet'!S$20="","",'Balance Sheet'!S$20)
A21: =IF('Balance Sheet'!P$21="","",'Balance Sheet'!P$21) -> Held-for-sale disposal proceeds proxy | B21: =SUMIF('Balance Sheet'!$K$1:$K$120,"Held-for-sale disposal proceeds proxy",'Balance Sheet'!$L$1:$L$120) -> 302000 | C21: =IF('Balance Sheet'!R$21="","",'Balance Sheet'!R$21) -> Completed asset disposals disclosed in Note 19, translated using disclosed average FX | D21: =IF('Balance Sheet'!S$21="","",'Balance Sheet'!S$21)
A22: =IF('Balance Sheet'!P$22="","",'Balance Sheet'!P$22) -> Indonesia Corridor disposal proceeds proxy | B22: =SUMIF('Balance Sheet'!$K$1:$K$120,"Indonesia Corridor disposal proceeds proxy",'Balance Sheet'!$L$1:$L$120) -> 376000 | C22: =IF('Balance Sheet'!R$22="","",'Balance Sheet'!R$22) -> Completed asset disposal disclosed in Note 17, translated using disclosed average FX | D22: =IF('Balance Sheet'!S$22="","",'Balance Sheet'!S$22)
A23: =IF('Balance Sheet'!P$23="","",'Balance Sheet'!P$23) -> Investing cash flow - observable subtotal | B23: =SUM(B17:B22) -> -4791000 | C23: =IF('Balance Sheet'!R$23="","",'Balance Sheet'!R$23) | D23: =IF('Balance Sheet'!S$23="","",'Balance Sheet'!S$23)
A24: =IF('Balance Sheet'!P$24="","",'Balance Sheet'!P$24) -> Cash flow from financing activities | B24: =IF('Balance Sheet'!Q$24="","",'Balance Sheet'!Q$24) | C24: =IF('Balance Sheet'!R$24="","",'Balance Sheet'!R$24) | D24: =IF('Balance Sheet'!S$24="","",'Balance Sheet'!S$24)
A25: =IF('Balance Sheet'!P$25="","",'Balance Sheet'!P$25) -> Net change in financial liabilities | B25: =(SUMIF('Balance Sheet'!$A$1:$A$90,"Non-current financial liabilities",'Balance Sheet'!$B$1:$B$90)+SUMIF('Balance Sheet'!$A$1:$A$90,"Current financial liabilities",'Balance Sheet'!$B$1:$B$90))-(SUMIF('Balance Sheet'!$A$1:$A$90,"Non-current financial liabilities",'Balance Sheet'!$C$1:$C$90)+SUMIF('Balance Sheet'!$A$1:$A$90,"Current financial liabilities",'Balance Sheet'!$C$1:$C$90)) -> 1050000 | C25: =IF('Balance Sheet'!R$25="","",'Balance Sheet'!R$25) -> Change in current and non-current financial liabilities | D25: =IF('Balance Sheet'!S$25="","",'Balance Sheet'!S$25)
A26: =IF('Balance Sheet'!P$26="","",'Balance Sheet'!P$26) -> Dividends and shareholder remuneration | B26: =SUMIF('Balance Sheet'!$A$1:$A$90,"Dividends and shareholder remuneration",'Balance Sheet'!$B$1:$B$90) -> -1388000 | C26: =IF('Balance Sheet'!R$26="","",'Balance Sheet'!R$26) -> Equity movement memo | D26: =IF('Balance Sheet'!S$26="","",'Balance Sheet'!S$26)
A27: =IF('Balance Sheet'!P$27="","",'Balance Sheet'!P$27) -> Treasury share cash flow | B27: =SUMIF('Balance Sheet'!$K$1:$K$120,"Net treasury share cash flow",'Balance Sheet'!$L$1:$L$120) -> -805000 | C27: =IF('Balance Sheet'!R$27="","",'Balance Sheet'!R$27) -> Market purchases, market sales and derivative settlements disclosed in notes | D27: =IF('Balance Sheet'!S$27="","",'Balance Sheet'!S$27)
A28: =IF('Balance Sheet'!P$28="","",'Balance Sheet'!P$28) -> Subordinated perpetual debentures cash flow | B28: =SUMIF('Balance Sheet'!$K$1:$K$120,"Net subordinated hybrid cash flow",'Balance Sheet'!$L$1:$L$120) -> 742000 | C28: =IF('Balance Sheet'!R$28="","",'Balance Sheet'!R$28) -> Hybrid issues less repurchases/redemptions disclosed in notes | D28: =IF('Balance Sheet'!S$28="","",'Balance Sheet'!S$28)
A29: =IF('Balance Sheet'!P$29="","",'Balance Sheet'!P$29) -> Other partner/scope/equity movements | B29: =SUMIF('Balance Sheet'!$A$1:$A$90,"Increases/(reductions) due to changes in scope",'Balance Sheet'!$B$1:$B$90)+SUMIF('Balance Sheet'!$A$1:$A$90,"Other transactions with partners or owners",'Balance Sheet'!$B$1:$B$90)+SUMIF('Balance Sheet'!$A$1:$A$90,"Other changes",'Balance Sheet'!$B$1:$B$90)+SUMIF('Balance Sheet'!$A$1:$A$90,"Share capital increase/(reduction)",'Balance Sheet'!$B$1:$B$90) -> 171000 | C29: =IF('Balance Sheet'!R$29="","",'Balance Sheet'!R$29) -> Equity movement memo items other than dividends, treasury shares and perpetual debentures | D29: =IF('Balance Sheet'!S$29="","",'Balance Sheet'!S$29)
A30: =IF('Balance Sheet'!P$30="","",'Balance Sheet'!P$30) -> Public grants received for hydrogen projects | B30: =SUMIF('Balance Sheet'!$K$1:$K$120,"Public grants received for hydrogen projects",'Balance Sheet'!$L$1:$L$120) -> 315000 | C30: =IF('Balance Sheet'!R$30="","",'Balance Sheet'!R$30) -> Funds received from public authorities disclosed in Note 19 | D30: =IF('Balance Sheet'!S$30="","",'Balance Sheet'!S$30)
A31: =IF('Balance Sheet'!P$31="","",'Balance Sheet'!P$31) -> Liabilities associated with held-for-sale assets | B31: =SUMIF('Balance Sheet'!$A$1:$A$90,"Liabilities associated with non-current assets held for sale",'Balance Sheet'!$B$1:$B$90)-SUMIF('Balance Sheet'!$A$1:$A$90,"Liabilities associated with non-current assets held for sale",'Balance Sheet'!$C$1:$C$90) -> 462000 | C31: =IF('Balance Sheet'!R$31="","",'Balance Sheet'!R$31) -> Change in related liability line | D31: =IF('Balance Sheet'!S$31="","",'Balance Sheet'!S$31)
A32: =IF('Balance Sheet'!P$32="","",'Balance Sheet'!P$32) -> Financing cash flow - observable subtotal | B32: =SUM(B25:B31) -> 547000 | C32: =IF('Balance Sheet'!R$32="","",'Balance Sheet'!R$32) | D32: =IF('Balance Sheet'!S$32="","",'Balance Sheet'!S$32)
A33: =IF('Balance Sheet'!P$33="","",'Balance Sheet'!P$33) -> Subtotal - independently sourced items (I + II + III) | B33: =B15+B23+B32 -> -284000 | C33: =IF('Balance Sheet'!R$33="","",'Balance Sheet'!R$33) | D33: =IF('Balance Sheet'!S$33="","",'Balance Sheet'!S$33) -> Subtotal before the explicit balance-sheet reconciliation line.
A34: =IF('Balance Sheet'!P$34="","",'Balance Sheet'!P$34) -> Reconciliation to actual cash movement | B34: =IF('Balance Sheet'!Q$34="","",'Balance Sheet'!Q$34) | C34: =IF('Balance Sheet'!R$34="","",'Balance Sheet'!R$34) | D34: =IF('Balance Sheet'!S$34="","",'Balance Sheet'!S$34)
A35: =IF('Balance Sheet'!P$35="","",'Balance Sheet'!P$35) -> Actual net increase/(decrease) in cash and cash equivalents (per Balance Sheet) | B35: =SUMIF('Balance Sheet'!$A$1:$A$90,"Cash and cash equivalents",'Balance Sheet'!$B$1:$B$90)-SUMIF('Balance Sheet'!$A$1:$A$90,"Cash and cash equivalents",'Balance Sheet'!$C$1:$C$90) -> -1497000 | C35: =IF('Balance Sheet'!R$35="","",'Balance Sheet'!R$35) -> Current-year cash less prior-year cash from the balance sheet | D35: =IF('Balance Sheet'!S$35="","",'Balance Sheet'!S$35)
A36: =IF('Balance Sheet'!P$36="","",'Balance Sheet'!P$36) -> Unreconciled / non-cash and other unallocated items | B36: =B35-B33 -> -1213000 | C36: =IF('Balance Sheet'!R$36="","",'Balance Sheet'!R$36) -> Actual balance-sheet cash movement less independently sourced subtotal | D36: =IF('Balance Sheet'!S$36="","",'Balance Sheet'!S$36) -> Visible reconciliation line, not an operating/investing/financing plug.
A37: =IF('Balance Sheet'!P$37="","",'Balance Sheet'!P$37) -> Net increase/(decrease) in cash and cash equivalents (= actual, by construction) | B37: =B33+B36 -> -1497000 | C37: =IF('Balance Sheet'!R$37="","",'Balance Sheet'!R$37) -> Subtotal plus visible reconciliation line | D37: =IF('Balance Sheet'!S$37="","",'Balance Sheet'!S$37)
A38: =IF('Balance Sheet'!P$38="","",'Balance Sheet'!P$38) -> Cash and cash equivalents at beginning of period | B38: =B5 -> 4758000 | C38: =IF('Balance Sheet'!R$38="","",'Balance Sheet'!R$38) | D38: =IF('Balance Sheet'!S$38="","",'Balance Sheet'!S$38)
A39: =IF('Balance Sheet'!P$39="","",'Balance Sheet'!P$39) -> Cash and cash equivalents at end of period | B39: =B38+B37 -> 3261000 | C39: =IF('Balance Sheet'!R$39="","",'Balance Sheet'!R$39) -> Reconciles to balance sheet cash by construction | D39: =IF('Balance Sheet'!S$39="","",'Balance Sheet'!S$39)
A40: =IF('Balance Sheet'!P$40="","",'Balance Sheet'!P$40) -> Check: ending cash per statement above vs. balance sheet | B40: =B39-SUMIF('Balance Sheet'!$A$1:$A$90,"Cash and cash equivalents",'Balance Sheet'!$B$1:$B$90) -> 0 | C40: =IF('Balance Sheet'!R$40="","",'Balance Sheet'!R$40) | D40: =IF('Balance Sheet'!S$40="","",'Balance Sheet'!S$40) -> Must be zero after the explicit reconciliation line.
